Workbook

Sheet tables
A1: ##var | B1: ##id注释 | C1: full_name | D1: value_type | E1: read_schema_from_file | F1: input | G1: index | H1: mode | I1: group | J1: comment | K1: tags | L1: output
A2: ## | C2: 全名(包含模块和名字) | D2: 记录类名 | E2: 从excel读取定义 | F2: 文件列表 | G2: 表id字段 | H2: 模式 | I2: 分组 | J2: 注释 | L2: 输出文件名
A3: ## | E3: false时取已有定义，true为从excel标题头和属性栏读取定义 | F3: 可以多个，以逗号','分隔 | G3: 为空的话自动取value_type中第一个字段,多主键联合索引为key1+key2,多主键独立索引为"key1,key2" | H3: 取值one|map|list，为空自动为map | I3: 取值c|s|e，可以有多个，以逗号','分隔。空则表示属于所有分组 | L3: 默认为 <module>_<name>.<suffix>
C4: TbL10nUI | D4: L10nUI | E4: 1 | F4: 多语言_UI@TableConfig.xlsx | G4: l10n_key
C5: TbL10nGame | D5: L10nGame | E5: 1 | F5: 多语言_游戏@TableConfig.xlsx | G5: l10n_key
C6: TbAudio | D6: Audio | E6: 1 | F6: 游戏_音频@TableConfig.xlsx | H6: one
C7: GameCore.TbGSingleton | D7: GameSingletonCfg | E7: 1 | F7: 游戏_单例@TableConfig.xlsx | H7: one
B8: 10001 | C8: GameActor.TbAdventurer | D8: AdventurerCfg | E8: 1 | F8: 角色_冒险者@TableConfig.xlsx
B9: 20001 | C9: GameActor.TbClass | D9: ClassCfg | E9: 1 | F9: 角色_职业@TableConfig.xlsx
B10: 30001 | C10: GameActor.TbSubrace | D10: SubraceCfg | E10: 1 | F10: 角色_种族_友方@TableConfig.xlsx,角色_种族_敌方@TableConfig.xlsx
B11: 40001 | C11: GameActor.TbItem | D11: ItemCfg | E11: 1 | F11: 角色_装备@TableConfig.xlsx,角色_奇物@TableConfig.xlsx
B12: 位标记 | C12: GameActor.TbWeaponBase | D12: WeaponBaseCfg | E12: 1 | F12: 角色_基础武器@TableConfig.xlsx
B13: 50001 | C13: GameActor.TbAbility | D13: AbilityCfg | E13: 1 | F13: 角色_能力@TableConfig.xlsx
B14: 60001 | C14: GameActor.TbPreset | D14: PresetCfg | E14: 1 | F14: 角色_预设_友方@TableConfig.xlsx,角色_预设_敌方@TableConfig.xlsx
B15: 70001 | C15: GameCombat.TbCampaign | D15: CampaignCfg | E15: 1 | F15: 战斗_战役@TableConfig.xlsx

Sheet beans
A1: ##var | B1: full_name | C1: parent | D1: valueType | E1: sep | F1: alias | G1: comment | H1: group | I1: tags | J1: *fields
A2: ##var | J2: name | K2: type | L2: group | M2: variants | N2: alias | O2: comment | P2: tags
A3: ## | B3: 全名 | E3: 分割符 | F3: 别名 | G3: 注释 | J3: 字段名 | K3: 类型 | L3: 分组 | M3: 变体 | N3: 别名 | O3: 注释
B4: GameCore.Dice | E4: & | F4: 骰子 | G4: =F4 -> 骰子 | J4: amount | K4: int | N4: 数量 | O4: =N4 -> 数量
J5: diceFaces | K5: int | N5: 骰子面数 | O5: =N5 -> 骰子面数
B6: GameActor.Damage | F6: 伤害 | G6: =F6 -> 伤害 | J6: dice | K6: GameCore.Dice | N6: 数值 | O6: =N6 -> 数值
J7: damageType | K7: GameActor.EmDamageType | N7: 类型 | O7: =N7 -> 类型
B8: GameActor.AttributePreset | F8: 角色预设 | G8: =F8 -> 角色预设 | J8: abilityScores | K8: GameActor.AbilityScore | N8: 能力值 | O8: =N8 -> 能力值
J9: resistance | K9: (map#sep=&|),GameActor.EmDamageType,float | N9: 伤害抗性 | O9: =N9 -> 伤害抗性
J10: armourClass | K10: int | N10: 护甲等级 | O10: =N10 -> 护甲等级
J11: movement | K11: int | N11: 移动力 | O11: =N11 -> 移动力
J12: initiative | K12: int | N12: 先攻 | O12: =N12 -> 先攻
J13: abilities | K13: array,int | N13: 能力 | O13: =N13 -> 能力
B14: GameActor.AbilityScore | F14: 能力值 | G14: =F14 -> 能力值 | J14: strength | K14: int | N14: 力量 | O14: =N14 -> 力量
J15: dexterity | K15: int | N15: 敏捷 | O15: =N15 -> 敏捷
J16: constitution | K16: int | N16: 体质 | O16: =N16 -> 体质
J17: intelligent | K17: int | N17: 智力 | O17: =N17 -> 智力
J18: wisdom | K18: int | N18: 感知 | O18: =N18 -> 感知
J19: charisma | K19: int | N19: 魅力 | O19: =N19 -> 魅力
B20: GameActor.ActorItemPreset | F20: 预设角色道具 | G20: =F20 -> 预设角色道具 | J20: mainHand | K20: int#ref=GameActor.TbItem? | N20: 主手 | O20: =N20 -> 主手
J21: offHand | K21: int#ref=GameActor.TbItem? | N21: 副手 | O21: =N21 -> 副手
J22: body | K22: int#ref=GameActor.TbItem? | N22: 甲 | O22: =N22 -> 甲
J23: artifacts | K23: array,(int#ref=GameActor.TbItem?) | N23: 奇物 | O23: =N23 -> 奇物
B24: GameActor.MaxHp | F24: 最大生命值 | G24: =F24 -> 最大生命值
B25: GameActor.MaxHpFromDice | C25: GameActor.MaxHp | E25: ^ | F25: 骰子生命值 | G25: =F25 -> 骰子生命值 | J25: dice | K25: GameCore.Dice | N25: 骰子 | O25: =N25 -> 骰子
J26: baseNumber | K26: int | N26: 基础值 | O26: =N26 -> 基础值
B27: GameActor.MaxHpFromClass | C27: GameActor.MaxHp | F27: 职业生命值 | G27: =F27 -> 职业生命值
B28: GameActor.ItemInfo | F28: 道具信息 | G28: =F28 -> 道具信息
B29: GameActor.EmptyInfo | C29: GameActor.ItemInfo | F29: 空占位符 | G29: 空占位符
B30: GameActor.WeaponInfo | C30: GameActor.ItemInfo | F30: 武器信息 | G30: =F30 -> 武器信息 | J30: type | K30: GameActor.EmEquipType | N30: 基础类型 | O30: =N30 -> 基础类型
B31: GameActor.NArmourInfo | C31: GameActor.ItemInfo | E31: | | F31: 无甲信息 | G31: =F31 -> 无甲信息
B32: GameActor.MArmourInfo | C32: GameActor.ItemInfo | E32: | | F32: 轻甲信息 | G32: =F32 -> 轻甲信息 | J32: armourClass | K32: int | N32: 护甲等级 | O32: 护甲等级
B33: GameActor.LArmourInfo | C33: GameActor.ItemInfo | E33: | | F33: 中甲信息 | G33: 中甲信息 | J33: armourClass | K33: int | N33: 护甲等级 | O33: 护甲等级
J34: limited | K34: int | N34: 调整值上限 | O34: =N34 -> 调整值上限
B35: GameActor.HArmourInfo | C35: GameActor.ItemInfo | E35: | | F35: 重甲信息 | G35: =F35 -> 重甲信息 | J35: armourClass | K35: int | N35: 护甲等级 | O35: 护甲等级
J36: equipNeed | K36: int | N36: 装备力量需求 | O36: =N36 -> 装备力量需求
B37: GameActor.ShieldInfo | C37: GameActor.ItemInfo | E37: | | F37: 盾牌信息 | G37: =F37 -> 盾牌信息 | J37: armourClass | K37: int | N37: 护甲等级 | O37: 护甲等级
B38: GameActor.ArtifactInfo | C38: GameActor.ItemInfo | F38: 奇物信息 | G38: 奇物信息
B39: GameCombat.SquadStance | F39: 战队队形 | J39: id | K39: int | N39: 角色id | O39: =N39 -> 角色id
J40: row | K40: int | N40: 排 | O40: =N40 -> 排
...

Sheet enums
A1: ##var | B1: full_name | C1: flags | D1: unique | E1: group | F1: comment | G1: tags | H1: *items
A2: ##var | H2: name | I2: alias | J2: value | K2: comment | L2: tags
A3: ## | B3: 全名(包含模块和名字) | C3: 是否为位标记枚举 | D3: 枚举项是否唯一 | H3: 枚举名 | I3: 别名 | J3: 值 | K3: 注释
B4: GameActor.EmAbilityScore | F4: 角色能力值 | H4: None | I4: 无 | J4: 0 | K4: =I4 -> 无
H5: Strength | I5: 力量 | J5: 1 | K5: 力量
H6: Dexterity | I6: 敏捷 | J6: 2 | K6: =I6 -> 敏捷
H7: Constitution | I7: 体质 | J7: 3 | K7: =I7 -> 体质
H8: Intelligent | I8: 智力 | J8: 4 | K8: =I8 -> 智力
H9: Wisdom | I9: 感知 | J9: 5 | K9: =I9 -> 感知
H10: Charisma | I10: 魅力 | J10: 6 | K10: =I10 -> 魅力
B11: GameActor.EmClass | C11: 0 | D11: 1 | F11: 职业 | H11: Barbarian | I11: 野蛮人 | J11: 20001 | K11: =I11 -> 野蛮人
H12: Bard | I12: 吟游诗人 | J12: 20002 | K12: =I12 -> 吟游诗人
H13: Cleric | I13: 牧师 | J13: 20003 | K13: =I13 -> 牧师
H14: Druid | I14: 德鲁伊 | J14: 20004 | K14: =I14 -> 德鲁伊
H15: Fighter | I15: 战士 | J15: 20005 | K15: =I15 -> 战士
H16: Monk | I16: 武僧 | J16: 20006 | K16: =I16 -> 武僧
H17: Paladin | I17: 圣武士 | J17: 20007 | K17: =I17 -> 圣武士
H18: Ranger | I18: 游侠 | J18: 20008 | K18: =I18 -> 游侠
H19: Rogue | I19: 游荡者 | J19: 20009 | K19: =I19 -> 游荡者
H20: Sorcerer | I20: 术士 | J20: 20010 | K20: =I20 -> 术士
H21: Warlock | I21: 邪术师 | J21: 20011 | K21: =I21 -> 邪术师
H22: Wizard | I22: 法师 | J22: 20012 | K22: =I22 -> 法师
B23: GameActor.EmDamageType | C23: 0 | D23: 1 | F23: 伤害类型 | H23: None | I23: 无 | J23: 0 | K23: =I23 -> 无
H24: Acid | I24: 强酸 | J24: 1 | K24: =I24 -> 强酸
H25: Cold | I25: 冰冻 | J25: 2 | K25: =I25 -> 冰冻
H26: Fire | I26: 火焰 | J26: 3 | K26: =I26 -> 火焰
H27: Lighting | I27: 闪电 | J27: 4 | K27: =I27 -> 闪电
H28: Poison | I28: 毒素 | J28: 5 | K28: =I28 -> 毒素
H29: Bludgeoning | I29: 钝击 | J29: 6 | K29: =I29 -> 钝击
H30: Piercing | I30: 穿刺 | J30: 7 | K30: =I30 -> 穿刺
H31: Slashing | I31: 挥砍 | J31: 8 | K31: =I31 -> 挥砍
B32: GameActor.EmWeaponType | C32: 0 | D32: 1 | F32: 武器类型 | H32: OneHand | I32: 单手 | J32: 1 | K32: =I32 -> 单手
H33: TwoHand | I33: 双手 | J33: 2 | K33: =I33 -> 双手
B34: GameActor.EmEquipType | C34: 1 | D34: 1 | F34: 基础武器 | H34: None | I34: 无 | J34: 0 | K34: =I34 -> 无
H35: NoArmour | I35: 无甲 | J35: 1 | K35: =I35 -> 无甲
H36: LightArmour | I36: 轻甲 | J36: 2 | K36: =I36 -> 轻甲
H37: MediumArmour | I37: 中甲 | J37: 4 | K37: =I37 -> 中甲
H38: HeavyArmour | I38: 重甲 | J38: 8 | K38: =I38 -> 重甲
H39: Shield | I39: 盾牌 | J39: 16 | K39: =I39 -> 盾牌
H40: Club | I40: 短棒 | J40: 32 | K40: =I40 -> 短棒
...

Sheet 多语言_UI
A1: ##var | B1: ##序列号 | C1: l10n_key | D1: cn | E1: en
A2: ##type | C2: string | D2: string | E2: string
A3: ## | C3: 语言key | D3: 中文 | E3: 英文
B4: 1 | C4: game_title | D4: 有趣的游戏 | E4: Funny Game
B5: 2 | C5: common_yes | D5: 是 | E5: Yes
B6: 3 | C6: common_no | D6: 否 | E6: No
B7: 4 | C7: common_help | D7: 帮助 | E7: Help
B8: 5 | C8: main_play | D8: 开始游戏 | E8: Play
B9: 6 | C9: main_new_game | D9: 新游戏 | E9: New Game
B10: 7 | C10: main_continue | D10: 继续游戏 | E10: Continue
B11: 8 | C11: main_load | D11: 加载游戏 | E11: Load
B12: 9 | C12: main_settings | D12: 设置 | E12: Settings
B13: 10 | C13: main_exit | D13: 退出游戏 | E13: Exit
B14: 11 | C14: settings_display | D14: 显示 | E14: Display
B15: 12 | C15: settings_windowed | D15: 窗口化 | E15: Windowed
... B22: 19 | C22: settings_sfx_vol | D22: 音效 | E22: Sfx

Sheet 多语言_游戏
A1: ##var | B1: ##序列号 | C1: l10n_key | D1: cn | E1: en
A2: ##type | C2: string | D2: string | E2: string
A3: ## | C3: 语言key | D3: 中文 | E3: 英文
B4: 1 | C4: game_name | D4: 有趣的游戏 | E4: Funny Game

Sheet 游戏_音频
A1: ##column##var | B1: ##type | C1: ##
C2: 描述 | D2: 资源名
A3: enter_btn | B3: string | C3: 按钮_悬停 | D3: sfx_button_enter
A4: click_btn | B4: string | C4: 按钮_点击 | D4: sfx_button_click
A5: enter_tgl | B5: string | C5: 切换_悬停 | D5: sfx_button_enter
A6: click_tgl | B6: string | C6: 切换_点击 | D6: sfx_button_click
A7: drag_bar_music | B7: string | C7: 进度条_拖拽_测试音乐 | D7: music_main_menu
A8: drag_bar_sfx | B8: string | C8: 进度条_拖拽_测试音效 | D8: sfx_button_enter
A9: main_menu_bgm | B9: string | C9: 主菜单_背景乐 | D9: music_main_menu
A10: game_bgm | B10: string | C10: 游戏_背景乐 | D10: music_game
A11: pop_out | B11: string | C11: 弹窗_弹出 | D11: sfx_pop_out
A12: pop_move | B12: string | C12: 弹窗_移动 | D12: sfx_pop_move
A13: pop_hide | B13: string | C13: 弹窗_隐藏 | D13: sfx_pop_hide

Sheet 游戏_单例
A1: ##column##var | B1: ##type | C1: ##
C2: 描述
A3: battle_map_length | B3: int | C3: 战役地图边长 | D3: 25
A4: battle_down_round_count_max | B4: int | C4: 战斗倒地回合计数上限 | D4: 3
A5: artifact_field | B5: int | C5: 奇物栏位数量上限 | D5: 3
A6: default_abilities | B6: (array#sep=|), int | C6: 默认能力 | D6: 50001

Sheet 角色_职业
A1: ##var | B1: id | C1: name
A2: ##type | B2: GameActor.EmClass | C2: string
A3: ## | B3: 唯一id | C3: 名字
B4: Barbarian | C4: 野蛮人
B5: Bard | C5: 吟游诗人
B6: Cleric | C6: 牧师
B7: Druid | C7: 德鲁伊
B8: Fighter | C8: 战士
B9: Monk | C9: 武僧
B10: Paladin | C10: 圣武士
B11: Ranger | C11: 游侠
B12: Rogue | C12: 游荡者
B13: Sorcerer | C13: 术士
B14: Warlock | C14: 邪术师
B15: Wizard | C15: 法师

Sheet 角色_种族_友方
A1: ##var | B1: id | C1: name | D1: race | E1: creature_type | F1: body_type | G1: proficiency | H1: attribute_preset | T1: ##能力表索引
A2: ##type | B2: int | C2: string | D2: GameActor.EmRace | E2: GameActor.EmCreatureType | F2: GameActor.EmBodyType | G2: GameActor.EmEquipType | H2: GameActor.AttributePreset
A3: ##type | H3: abilityScores | N3: resistance | O3: armourClass | P3: movement | Q3: initiative | R3: abilities
A4: ##type | H4: Strength | I4: Dexterity | J4: Constitution | K4: Intelligent | L4: Wisdom | M4: Charisma
A5: ## | B5: 唯一id | C5: 名称 | D5: 种族 | E5: 类别 | F5: 体型 | G5: 装备熟练 | H5: 力量 | I5: 敏捷 | J5: 体质 | K5: 智力 | L5: 感知 | M5: 魅力 | N5: 伤害抗性 | O5: 护甲等级 | P5: 移动力 | Q5: 先攻 | R5: 能力表
B6: 30001 | C6: 人类 | D6: 人类 | E6: 类人 | F6: 中型 | G6: 简易武器|轻甲|中甲 | H6: 1 | I6: 1 | J6: 1 | K6: 1 | L6: 1 | M6: 1 | N6: 无&0 | O6: 10 | P6: 6 | Q6: 0 | T6: =IF(R6="","",IFERROR(VLOOKUP(R6,角色_能力!B:C,2,FALSE),"ERROR")) | U6: =IF(S6="","",IFERROR(VLOOKUP(S6,角色_能力!B:C,2,FALSE),"ERROR"))
B7: 30002 | C7: 丘陵矮人 | D7: 矮人 | E7: 类人 | F7: 中型 | G7: 简易武器|中甲|重甲|战斧|战锤 | H7: 0 | I7: 0 | J7: 2 | K7: 0 | L7: 2 | M7: 0 | N7: 毒素&0.5 | O7: 10 | P7: 5 | Q7: 0 | R7: 50011 | T7: =IF(R7="","",IFERROR(VLOOKUP(R7,角色_能力!B:C,2,FALSE),"ERROR")) -> 矮人坚韧 | U7: =IF(S7="","",IFERROR(VLOOKUP(S7,角色_能力!B:C,2,FALSE),"ERROR"))
B8: 30003 | C8: 高山矮人 | D8: 矮人 | E8: 类人 | F8: 中型 | G8: 简易武器|中甲|重甲|战斧|战锤 | H8: 2 | I8: 0 | J8: 2 | K8: 0 | L8: 0 | M8: 0 | N8: 毒素&0.5 | O8: 10 | P8: 5 | Q8: 0 | R8: 50011 | T8: =IF(R8="","",IFERROR(VLOOKUP(R8,角色_能力!B:C,2,FALSE),"ERROR")) -> 矮人坚韧 | U8: =IF(S8="","",IFERROR(VLOOKUP(S8,角色_能力!B:C,2,FALSE),"ERROR"))
B9: 30004 | C9: 木精灵 | D9: 精灵 | E9: 类人 | F9: 中型 | G9: 简易武器|短弓|长弓 | H9: 0 | I9: 2 | J9: 0 | K9: 0 | L9: 1 | M9: 0 | N9: 无&0 | O9: 10 | P9: 7 | Q9: 0 | T9: =IF(R9="","",IFERROR(VLOOKUP(R9,角色_能力!B:C,2,FALSE),"ERROR")) | U9: =IF(S9="","",IFERROR(VLOOKUP(S9,角色_能力!B:C,2,FALSE),"ERROR"))
B10: 30005 | C10: 高精灵 | D10: 精灵 | E10: 类人 | F10: 中型 | G10: 简易武器 | H10: 0 | I10: 2 | J10: 0 | K10: 0 | L10: 1 | M10: 0 | N10: 无&0 | O10: 10 | P10: 7 | Q10: 0 | R10: 51201 | S10: 51202 | T10: =IF(R10="","",IFERROR(VLOOKUP(R10,角色_能力!B:C,2,FALSE),"ERROR")) -> 冷冻射线 | U10: =IF(S10="","",IFERROR(VLOOKUP(S10,角色_能力!B:C,2,FALSE),"ERROR")) -> 火焰箭
B11: 30006 | C11: 半身人 | D11: 半身人 | E11: 类人 | F11: 小型 | G11: 简易武器 | H11: 0 | I11: 2 | J11: 0 | K11: 0 | L11: 0 | M11: 1 | N11: 无&0 | O11: 10 | P11: 5 | Q11: 0 | R11: 50013 | T11: =IF(R11="","",IFERROR(VLOOKUP(R11,角色_能力!B:C,2,FALSE),"ERROR")) -> 幸运 | U11: =IF(S11="","",IFERROR(VLOOKUP(S11,角色_能力!B:C,2,FALSE),"ERROR"))
B12: 30007 | C12: 侏儒 | D12: 侏儒 | E12: 类人 | F12: 小型 | G12: 简易武器 | H12: 0 | I12: 1 | J12: 0 | K12: 2 | L12: 0 | M12: 0 | N12: 无&0 | O12: 10 | P12: 5 | Q12: 0 | R12: 50014 | T12: =IF(R12="","",IFERROR(VLOOKUP(R12,角色_能力!B:C,2,FALSE),"ERROR")) -> 侏儒狡黠 | U12: =IF(S12="","",IFERROR(VLOOKUP(S12,角色_能力!B:C,2,FALSE),"ERROR"))
B13: 30008 | C13: 半精灵 | D13: 半精灵 | E13: 类人 | F13: 中型 | G13: 简易武器|长剑|长弓 | H13: 0 | I13: 1 | J13: 0 | K13: 1 | L13: 0 | M13: 2 | N13: 无&0 | O13: 10 | P13: 6 | Q13: 0 | T13: =IF(R13="","",IFERROR(VLOOKUP(R13,角色_能力!B:C,2,FALSE),"ERROR")) | U13: =IF(S13="","",IFERROR(VLOOKUP(S13,角色_能力!B:C,2,FALSE),"ERROR"))
B14: 30009 | C14: 龙裔 | D14: 龙裔 | E14: 类人 | F14: 中型 | G14: 简易武器 | H14: 2 | I14: 0 | J14: 0 | K14: 0 | L14: 0 | M14: 1 | N14: 无&0 | O14: 13 | P14: 6 | Q14: 0 | R14: 50015 | T14: =IF(R14="","",IFERROR(VLOOKUP(R14,角色_能力!B:C,2,FALSE),"ERROR")) -> 吐息武器 | U14: =IF(S14="","",IFERROR(VLOOKUP(S14,角色_能力!B:C,2,FALSE),"ERROR"))
B15: 30010 | C15: 半兽人 | D15: 半兽人 | E15: 类人 | F15: 中型 | G15: 简易武器 | H15: 2 | I15: 0 | J15: 1 | K15: 0 | L15: 0 | M15: 0 | N15: 无&0 | O15: 10 | P15: 6 | Q15: 0 | R15: 50012 | T15: =IF(R15="","",IFERROR(VLOOKUP(R15,角色_能力!B:C,2,FALSE),"ERROR")) -> 凶蛮攻击 | U15: =IF(S15="","",IFERROR(VLOOKUP(S15,角色_能力!B:C,2,FALSE),"ERROR"))
B16: 30011 | C16: 提夫林 | D16: 提夫林 | E16: 类人 | F16: 中型 | G16: 简易武器 | H16: 0 | I16: 0 | J16: 0 | K16: 1 | L16: 0 | M16: 2 | N16: 火焰&0.5 | O16: 10 | P16: 6 | Q16: 0 | R16: 50016 | T16: =IF(R16="","",IFERROR(VLOOKUP(R16,角色_能力!B:C,2,FALSE),"ERROR")) -> 炼狱叱喝 | U16: =IF(S16="","",IFERROR(VLOOKUP(S16,角色_能力!B:C,2,FALSE),"ERROR"))

Sheet 角色_冒险者
A1: ##var | B1: id | C1: name | D1: subrace | E1: ##亚种索引 | F1: level | G1: clasz | K1: expOnKilled | L1: max_hp | O1: attribute_preset | AB1: ##能力表索引 | AE1: item_preset1 | AK1: item_preset2 | AQ1: ##道具预设id索引 | BC1: knapsack_items
A2: ##type | B2: int | C2: string | D2: int#ref=GameActor.TbSubrace | F2: int | G2: map,GameActor.EmClass,int | K2: int | L2: GameActor.MaxHp | O2: GameActor.AttributePreset | AE2: GameActor.ActorItemPreset | AK2: GameActor.ActorItemPreset | BC2: map,(int#ref=GameActor.TbItem),float
A3: ##type | L3: $type | O3: abilityScores | U3: resistance | V3: armourClass | W3: movement | X3: initiative | Y3: abilities
A4: ##type | O4: Strength | P4: Dexterity | Q4: Constitution | R4: Intelligent | S4: Wisdom | T4: Charisma | AE4: MainHand | AF4: OffHand | AG4: Body | AH4: Artifacts | AK4: MainHand | AL4: OffHand | AM4: Body | AN4: Artifacts
A5: ## | B5: 唯一id | C5: 名称 | D5: 亚种 | F5: 角色等级 | G5: 职业 | H5: 等级 | I5: 职业 | J5: 等级 | K5: 击杀经验 | L5: 生命值类型 | M5: 加成 | O5: 力量 | P5: 敏捷 | Q5: 体质 | R5: 智力 | S5: 感知 | T5: 魅力 | U5: 伤害抗性 | V5: 护甲等级 | W5: 移动力 | X5: 先攻 | Y5: 能力表 | AE5: 主手装备 | AF5: 副手装备 | AG5: 身体装备 | AH5: 奇物 | AK5: 主手装备 | AL5: 副手装备 | AM5: 身体装备 | AN5: 奇物 | AQ5: 主手装备 | AR5: 副手装备 | AS5: 身体装备 | AT5: 奇物 | AW5: 主手装备 | AX5: 副手装备 | AY5: 身体装备 | AZ5: 奇物 | BC5: 道具id | BD5: 出现概率 | BE5: 道具id | BF5: 出现概率 | BG5: 道具id | BH5: 出现概率
B6: 10001 | C6: 安缇洛雅·阿玛斯塔夏 | D6: 30005 | E6: =IF(D6="","",IFERROR(VLOOKUP(D6,角色_种族_友方!B:C,2,FALSE),"ERROR")) -> 高精灵 | F6: =H6+J6 -> 2 | G6: 圣武士 | H6: 2 | K6: 0 | L6: 职业生命值 | O6: 18 | P6: 15 | Q6: 16 | R6: 12 | S6: 14 | T6: 17 | U6: 无&0 | V6: 16 | W6: 6 | X6: 2 | Y6: 50701 | Z6: 50702 | AB6: =IF(Y6="","",IFERROR(VLOOKUP(Y6,角色_能力!B:C,2,FALSE),"ERROR")) -> 至圣斩 | AC6: =IF(Z6="","",IFERROR(VLOOKUP(Z6,角色_能力!B:C,2,FALSE),"ERROR")) -> 圣疗术 | AE6: 42702 | AF6: 40501 | AG6: 40402 | AK6: 0 | AL6: 0 | AM6: 0 | AQ6: =IF(AE6=0,"无",IFERROR(VLOOKUP(AE6,角色_装备!B:C,2,FALSE),"ERROR")) -> 辉黯 | AR6: =IF(AF6=0,"无",IFERROR(VLOOKUP(AF6,角色_装备!B:C,2,FALSE),"ERROR")) -> 盾牌 | AS6: =IF(AG6=0,"无",IFERROR(VLOOKUP(AG6,角色_装备!B:C,2,FALSE),"ERROR")) -> 链甲 | AW6: =IF(AK6=0,"无",IFERROR(VLOOKUP(AK6,角色_装备!B:C,2,FALSE),"ERROR")) -> 无 | AX6: =IF(AL6=0,"无",IFERROR(VLOOKUP(AL6,角色_装备!B:C,2,FALSE),"ERROR")) -> 无 | AY6: =IF(AM6=0,"无",IFERROR(VLOOKUP(AM6,角色_装备!B:C,2,FALSE),"ERROR")) -> 无
B7: 10002 | C7: 索林·白须 | D7: 30003 | E7: =IF(D7="","",IFERROR(VLOOKUP(D7,角色_种族_友方!B:C,2,FALSE),"ERROR")) -> 高山矮人 | F7: =H7+J7 -> 2 | G7: 战士 | H7: 2 | K7: 0 | L7: 职业生命值 | O7: 20 | P7: 16 | Q7: 17 | R7: 8 | S7: 11 | T7: 14 | U7: 无&0 | V7: 16 | W7: 5 | X7: 3 | Y7: 50501 | Z7: 50502 | AA7: 50503 | AB7: =IF(Y7="","",IFERROR(VLOOKUP(Y7,角色_能力!B:C,2,FALSE),"ERROR")) -> 回气 | AC7: =IF(Z7="","",IFERROR(VLOOKUP(Z7,角色_能力!B:C,2,FALSE),"ERROR")) -> 动作如潮 | AE7: 41901 | AF7: 0 | AG7: 40402 | AK7: 0 | AL7: 0 | AM7: 0 | AQ7: =IF(AE7=0,"无",IFERROR(VLOOKUP(AE7,角色_装备!B:C,2,FALSE),"ERROR")) -> 巨斧 | AR7: =IF(AF7=0,"无",IFERROR(VLOOKUP(AF7,角色_装备!B:C,2,FALSE),"ERROR")) -> 无 | AS7: =IF(AG7=0,"无",IFERROR(VLOOKUP(AG7,角色_装备!B:C,2,FALSE),"ERROR")) -> 链甲 | AW7: =IF(AK7=0,"无",IFERROR(VLOOKUP(AK7,角色_装备!B:C,2,FALSE),"ERROR")) -> 无 | AX7: =IF(AL7=0,"无",IFERROR(VLOOKUP(AL7,角色_装备!B:C,2,FALSE),"ERROR")) -> 无 | AY7: =IF(AM7=0,"无",IFERROR(VLOOKUP(AM7,角色_装备!B:C,2,FALSE),"ERROR")) -> 无
B8: 10003 | C8: 彻宁·格拉尔 | D8: 30001 | E8: =IF(D8="","",IFERROR(VLOOKUP(D8,角色_种族_友方!B:C,2,FALSE),"ERROR")) -> 人类 | F8: =H8+J8 -> 2 | G8: 游侠 | H8: 2 | K8: 0 | L8: 职业生命值 | O8: 16 | P8: 16 | Q8: 14 | R8: 12 | S8: 14 | T8: 12 | U8: 无&0 | V8: 14 | W8: 6 | X8: 3 | Y8: 50801 | AB8: =IF(Y8="","",IFERROR(VLOOKUP(Y8,角色_能力!B:C,2,FALSE),"ERROR")) -> 自然探索者 | AC8: =IF(Z8="","",IFERROR(VLOOKUP(Z8,角色_能力!B:C,2,FALSE),"ERROR")) | AE8: 42301 | AF8: 0 | AG8: 40202 | AK8: 43001 | AL8: 0 | AM8: 40202 | AQ8: =IF(AE8=0,"无",IFERROR(VLOOKUP(AE8,角色_装备!B:C,2,FALSE),"ERROR")) -> 长矛 | AR8: =IF(AF8=0,"无",IFERROR(VLOOKUP(AF8,角色_装备!B:C,2,FALSE),"ERROR")) -> 无 | AS8: =IF(AG8=0,"无",IFERROR(VLOOKUP(AG8,角色_装备!B:C,2,FALSE),"ERROR")) -> 皮甲 | AW8: =IF(AK8=0,"无",IFERROR(VLOOKUP(AK8,角色_装备!B:C,2,FALSE),"ERROR")) -> 长弓 | AX8: =IF(AL8=0,"无",IFERROR(VLOOKUP(AL8,角色_装备!B:C,2,FALSE),"ERROR")) -> 无 | AY8: =IF(AM8=0,"无",IFERROR(VLOOKUP(AM8,角色_装备!B:C,2,FALSE),"ERROR")) -> 皮甲
B9: 10004 | C9: 凯芙拉·斯托维恩 | D9: 30001 | E9: =IF(D9="","",IFERROR(VLOOKUP(D9,角色_种族_友方!B:C,2,FALSE),"ERROR")) -> 人类 | F9: =H9+J9 -> 2 | G9: 牧师 | H9: 2 | K9: 0 | L9: 职业生命值 | O9: 15 | P9: 10 | Q9: 14 | R9: 12 | S9: 18 | T9: 12 | U9: 无&0 | V9: 16 | W9: 6 | X9: 0 | Y9: 50301 | Z9: 50302 | AA9: 50303 | AB9: =IF(Y9="","",IFERROR(VLOOKUP(Y9,角色_能力!B:C,2,FALSE),"ERROR")) -> 圣火术 | AC9: =IF(Z9="","",IFERROR(VLOOKUP(Z9,角色_能力!B:C,2,FALSE),"ERROR")) -> 祝福术 | AE9: 40601 | AF9: 40501 | AG9: 40303 | AK9: 0 | AL9: 0 | AM9: 0 | AQ9: =IF(AE9=0,"无",IFERROR(VLOOKUP(AE9,角色_装备!B:C,2,FALSE),"ERROR")) -> 短棒 | AR9: =IF(AF9=0,"无",IFERROR(VLOOKUP(AF9,角色_装备!B:C,2,FALSE),"ERROR")) -> 盾牌 | AS9: =IF(AG9=0,"无",IFERROR(VLOOKUP(AG9,角色_装备!B:C,2,FALSE),"ERROR")) -> 鳞甲 | AW9: =IF(AK9=0,"无",IFERROR(VLOOKUP(AK9,角色_装备!B:C,2,FALSE),"ERROR")) -> 无 | AX9: =IF(AL9=0,"无",IFERROR(VLOOKUP(AL9,角色_装备!B:C,2,FALSE),"ERROR")) -> 无 | AY9: =IF(AM9=0,"无",IFERROR(VLOOKUP(AM9,角色_装备!B:C,2,FALSE),"ERROR")) -> 无
B10: 10005 | C10: 梅·文 | D10: 30008 | E10: =IF(D10="","",IFERROR(VLOOKUP(D10,角色_种族_友方!B:C,2,FALSE),"ERROR")) -> 半精灵 | F10: =H10+J10 -> 2 | G10: 吟游诗人 | H10: 2 | K10: 0 | L10: 职业生命值 | O10: 10 | P10: 18 | Q10: 12 | R10: 14 | S10: 14 | T10: 18 | U10: 无&0 | V10: 15 | W10: 6 | X10: 4 | Y10: 50201 | Z10: 50202 | AA10: 50203 | AB10: =IF(Y10="","",IFERROR(VLOOKUP(Y10,角色_能力!B:C,2,FALSE),"ERROR")) -> 诗人激励 | AC10: =IF(Z10="","",IFERROR(VLOOKUP(Z10,角色_能力!B:C,2,FALSE),"ERROR")) -> 恶言相加 | AE10: 40701 | AF10: 0 | AG10: 40202 | AK10: 0 | AL10: 0 | AM10: 0 | AQ10: =IF(AE10=0,"无",IFERROR(VLOOKUP(AE10,角色_装备!B:C,2,FALSE),"ERROR")) -> 匕首 | AR10: =IF(AF10=0,"无",IFERROR(VLOOKUP(AF10,角色_装备!B:C,2,FALSE),"ERROR")) -> 无 | AS10: =IF(AG10=0,"无",IFERROR(VLOOKUP(AG10,角色_装备!B:C,2,FALSE),"ERROR")) -> 皮甲 | AW10: =IF(AK10=0,"无",IFERROR(VLOOKUP(AK10,角色_装备!B:C,2,FALSE),"ERROR")) -> 无 | AX10: =IF(AL10=0,"无",IFERROR(VLOOKUP(AL10,角色_装备!B:C,2,FALSE),"ERROR")) -> 无 | AY10: =IF(AM10=0,"无",IFERROR(VLOOKUP(AM10,角色_装备!B:C,2,FALSE),"ERROR")) -> 无
B11: 10006 | C11: 米亚斯坦·樱木 | D11: 30009 | E11: =IF(D11="","",IFERROR(VLOOKUP(D11,角色_种族_友方!B:C,2,FALSE),"ERROR")) -> 龙裔 | F11: =H11+J11 -> 2 | G11: 术士 | H11: 2 | K11: 0 | L11: 职业生命值 | O11: 8 | P11: 18 | Q11: 16 | R11: 11 | S11: 12 | T11: 18 | U11: 无&0 | V11: 17 | W11: 6 | X11: 4 | Y11: 51202 | Z11: 51001 | AA11: 51002 | AB11: =IF(Y11="","",IFERROR(VLOOKUP(Y11,角色_能力!B:C,2,FALSE),"ERROR")) -> 火焰箭 | AC11: =IF(Z11="","",IFERROR(VLOOKUP(Z11,角色_能力!B:C,2,FALSE),"ERROR")) -> 魔法飞弹 | AE11: 40701 | AF11: 0 | AG11: 40101 | AK11: 0 | AL11: 0 | AM11: 0 | AQ11: =IF(AE11=0,"无",IFERROR(VLOOKUP(AE11,角色_装备!B:C,2,FALSE),"ERROR")) -> 匕首 | AR11: =IF(AF11=0,"无",IFERROR(VLOOKUP(AF11,角色_装备!B:C,2,FALSE),"ERROR")) -> 无 | AS11: =IF(AG11=0,"无",IFERROR(VLOOKUP(AG11,角色_装备!B:C,2,FALSE),"ERROR")) -> 布袍 | AW11: =IF(AK11=0,"无",IFERROR(VLOOKUP(AK11,角色_装备!B:C,2,FALSE),"ERROR")) -> 无 | AX11: =IF(AL11=0,"无",IFERROR(VLOOKUP(AL11,角色_装备!B:C,2,FALSE),"ERROR")) -> 无 | AY11: =IF(AM11=0,"无",IFERROR(VLOOKUP(AM11,角色_装备!B:C,2,FALSE),"ERROR")) -> 无

Sheet 角色_预设_友方
A1: ##var | B1: id | C1: name | D1: subrace | E1: ##亚种索引 | F1: level | G1: clasz | K1: expOnKilled | L1: max_hp | O1: attribute_preset | AB1: ##能力表索引 | AE1: item_preset1 | AK1: item_preset2 | AQ1: ##道具预设id索引 | BC1: knapsack_items
A2: ##type | B2: int | C2: string | D2: int#ref=GameActor.TbSubrace | F2: int | G2: map,GameActor.EmClass,int | K2: int | L2: GameActor.MaxHp | O2: GameActor.AttributePreset | AE2: GameActor.ActorItemPreset | AK2: GameActor.ActorItemPreset | BC2: map,(int#ref=GameActor.TbItem),float
A3: ##type | L3: $type | O3: abilityScores | U3: resistance | V3: armourClass | W3: movement | X3: initiative | Y3: abilities
A4: ##type | O4: Strength | P4: Dexterity | Q4: Constitution | R4: Intelligent | S4: Wisdom | T4: Charisma | AE4: MainHand | AF4: OffHand | AG4: Body | AH4: Artifacts | AK4: MainHand | AL4: OffHand | AM4: Body | AN4: Artifacts
A5: ## | B5: 唯一id | C5: 名称 | D5: 亚种 | F5: 角色等级 | G5: 职业 | H5: 等级 | I5: 职业 | J5: 等级 | K5: 击杀经验 | L5: 生命值类型 | M5: 加成 | O5: 力量 | P5: 敏捷 | Q5: 体质 | R5: 智力 | S5: 感知 | T5: 魅力 | U5: 伤害抗性 | V5: 护甲等级 | W5: 移动力 | X5: 先攻 | Y5: 能力表 | AE5: 主手装备 | AF5: 副手装备 | AG5: 身体装备 | AH5: 奇物 | AK5: 主手装备 | AL5: 副手装备 | AM5: 身体装备 | AN5: 奇物 | AQ5: 主手装备 | AR5: 副手装备 | AS5: 身体装备 | AT5: 奇物 | AW5: 主手装备 | AX5: 副手装备 | AY5: 身体装备 | AZ5: 奇物 | BC5: 道具id | BD5: 出现概率 | BE5: 道具id | BF5: 出现概率 | BG5: 道具id | BH5: 出现概率
B6: 60001 | C6: 人类平民 | D6: 30001 | E6: =IF(D6="","",IFERROR(VLOOKUP(D6,角色_种族_友方!B:C,2,FALSE),"ERROR")) -> 人类 | F6: 1 | G6: 战士 | H6: 1 | K6: 0 | L6: 职业生命值 | O6: 10 | P6: 10 | Q6: 10 | R6: 10 | S6: 10 | T6: 10 | U6: 无&0 | V6: 10 | W6: 6 | X6: 0 | AB6: =IF(Y6="","",IFERROR(VLOOKUP(Y6,角色_能力!B:C,2,FALSE),"ERROR")) | AC6: =IF(Z6="","",IFERROR(VLOOKUP(Z6,角色_能力!B:C,2,FALSE),"ERROR")) | AE6: 40601 | AF6: 0 | AG6: 0 | AK6: 0 | AL6: 0 | AM6: 0 | AQ6: =IF(AE6=0,"无",IFERROR(VLOOKUP(AE6,角色_装备!B:C,2,FALSE),"ERROR")) -> 短棒 | AR6: =IF(AF6=0,"无",IFERROR(VLOOKUP(AF6,角色_装备!B:C,2,FALSE),"ERROR")) -> 无 | AS6: =IF(AG6=0,"无",IFERROR(VLOOKUP(AG6,角色_装备!B:C,2,FALSE),"ERROR")) -> 无 | AW6: =IF(AK6=0,"无",IFERROR(VLOOKUP(AK6,角色_装备!B:C,2,FALSE),"ERROR")) -> 无 | AX6: =IF(AL6=0,"无",IFERROR(VLOOKUP(AL6,角色_装备!B:C,2,FALSE),"ERROR")) -> 无 | AY6: =IF(AM6=0,"无",IFERROR(VLOOKUP(AM6,角色_装备!B:C,2,FALSE),"ERROR")) -> 无
B7: 60002 | C7: 商队护卫 | D7: 30001 | E7: 人类 | F7: 1 | G7: 战士 | H7: 1 | L7: 职业生命值 | O7: 12 | P7: 10 | Q7: 10 | R7: 10 | S7: 10 | T7: 10 | U7: 无&0 | V7: 16 | W7: 6 | X7: 0 | AE7: 41301 | AF7: 40501 | AG7: 40303 | AK7: 0 | AL7: 0 | AM7: 0 | AQ7: =IF(AE7=0,"无",IFERROR(VLOOKUP(AE7,角色_装备!B:C,2,FALSE),"ERROR")) -> 矛 | AR7: =IF(AF7=0,"无",IFERROR(VLOOKUP(AF7,角色_装备!B:C,2,FALSE),"ERROR")) -> 盾牌 | AS7: =IF(AG7=0,"无",IFERROR(VLOOKUP(AG7,角色_装备!B:C,2,FALSE),"ERROR")) -> 鳞甲 | AW7: =IF(AK7=0,"无",IFERROR(VLOOKUP(AK7,角色_装备!B:C,2,FALSE),"ERROR")) -> 无 | AX7: =IF(AL7=0,"无",IFERROR(VLOOKUP(AL7,角色_装备!B:C,2,FALSE),"ERROR")) -> 无 | AY7: =IF(AM7=0,"无",IFERROR(VLOOKUP(AM7,角色_装备!B:C,2,FALSE),"ERROR")) -> 无
B8: 60003 | C8: 商队弩手 | D8: 30001 | E8: 人类 | F8: 1 | G8: 战士 | H8: 1 | L8: 职业生命值 | O8: 10 | P8: 12 | Q8: 10 | R8: 10 | S8: 10 | T8: 10 | U8: 无&0 | V8: 13 | W8: 6 | X8: 0 | AE8: 42901 | AF8: 0 | AG8: 40301 | AK8: 40701 | AL8: 0 | AM8: 0 | AQ8: =IF(AE8=0,"无",IFERROR(VLOOKUP(AE8,角色_装备!B:C,2,FALSE),"ERROR")) -> 重弩 | AR8: =IF(AF8=0,"无",IFERROR(VLOOKUP(AF8,角色_装备!B:C,2,FALSE),"ERROR")) -> 无 | AS8: =IF(AG8=0,"无",IFERROR(VLOOKUP(AG8,角色_装备!B:C,2,FALSE),"ERROR")) -> 兽皮甲 | AW8: =IF(AK8=0,"无",IFERROR(VLOOKUP(AK8,角色_装备!B:C,2,FALSE),"ERROR")) -> 匕首 | AX8: =IF(AL8=0,"无",IFERROR(VLOOKUP(AL8,角色_装备!B:C,2,FALSE),"ERROR")) -> 无 | AY8: =IF(AM8=0,"无",IFERROR(VLOOKUP(AM8,角色_装备!B:C,2,FALSE),"ERROR")) -> 无
B9: 60004 | C9: 商队领袖·矮人 | D9: 30002 | E9: 丘陵矮人 | F9: 1 | G9: 战士 | H9: 1 | L9: 职业生命值 | O9: 12 | P9: 8 | Q9: 14 | R9: 10 | S9: 10 | T9: 12 | U9: 无&0 | V9: 18 | W9: 5 | X9: -1 | AE9: 42701 | AF9: 40501 | AG9: 40402 | AK9: 0 | AL9: 0 | AM9: 0 | AQ9: =IF(AE9=0,"无",IFERROR(VLOOKUP(AE9,角色_装备!B:C,2,FALSE),"ERROR")) -> 战锤 | AR9: =IF(AF9=0,"无",IFERROR(VLOOKUP(AF9,角色_装备!B:C,2,FALSE),"ERROR")) -> 盾牌 | AS9: =IF(AG9=0,"无",IFERROR(VLOOKUP(AG9,角色_装备!B:C,2,FALSE),"ERROR")) -> 链甲 | AW9: =IF(AK9=0,"无",IFERROR(VLOOKUP(AK9,角色_装备!B:C,2,FALSE),"ERROR")) -> 无 | AX9: =IF(AL9=0,"无",IFERROR(VLOOKUP(AL9,角色_装备!B:C,2,FALSE),"ERROR")) -> 无 | AY9: =IF(AM9=0,"无",IFERROR(VLOOKUP(AM9,角色_装备!B:C,2,FALSE),"ERROR")) -> 无
B10: 60005 | C10: 矮人勇士 | D10: 30003 | E10: 高山矮人 | F10: 1 | G10: 战士 | H10: 1 | L10: 职业生命值 | O10: 14 | P10: 8 | Q10: 16 | R10: 10 | S10: 8 | T10: 10 | U10: 无&0 | V10: 18 | W10: 5 | X10: -1 | Y10: 50501 | AE10: 41701 | AF10: 40501 | AG10: 40402 | AK10: 0 | AL10: 0 | AM10: 0 | AQ10: =IF(AE10=0,"无",IFERROR(VLOOKUP(AE10,角色_装备!B:C,2,FALSE),"ERROR")) -> 战斧 | AR10: =IF(AF10=0,"无",IFERROR(VLOOKUP(AF10,角色_装备!B:C,2,FALSE),"ERROR")) -> 盾牌 | AS10: =IF(AG10=0,"无",IFERROR(VLOOKUP(AG10,角色_装备!B:C,2,FALSE),"ERROR")) -> 链甲 | AW10: =IF(AK10=0,"无",IFERROR(VLOOKUP(AK10,角色_装备!B:C,2,FALSE),"ERROR")) -> 无 | AX10: =IF(AL10=0,"无",IFERROR(VLOOKUP(AL10,角色_装备!B:C,2,FALSE),"ERROR")) -> 无 | AY10: =IF(AM10=0,"无",IFERROR(VLOOKUP(AM10,角色_装备!B:C,2,FALSE),"ERROR")) -> 无
B11: 60006 | C11: 矮人碎铁近卫 | D11: 30003 | E11: 高山矮人 | F11: 5 | G11: 战士 | H11: 5 | L11: 职业生命值 | O11: 16 | P11: 10 | Q11: 18 | R11: 10 | S11: 8 | T11: 12 | U11: 无&0 | V11: 20 | W11: 5 | X11: 0 | Y11: 50501 | AE11: 42701 | AF11: 40501 | AG11: 40404 | AK11: 0 | AL11: 0 | AM11: 0 | AQ11: =IF(AE11=0,"无",IFERROR(VLOOKUP(AE11,角色_装备!B:C,2,FALSE),"ERROR")) -> 战锤 | AR11: =IF(AF11=0,"无",IFERROR(VLOOKUP(AF11,角色_装备!B:C,2,FALSE),"ERROR")) -> 盾牌 | AS11: =IF(AG11=0,"无",IFERROR(VLOOKUP(AG11,角色_装备!B:C,2,FALSE),"ERROR")) -> 板甲 | AW11: =IF(AK11=0,"无",IFERROR(VLOOKUP(AK11,角色_装备!B:C,2,FALSE),"ERROR")) -> 无 | AX11: =IF(AL11=0,"无",IFERROR(VLOOKUP(AL11,角色_装备!B:C,2,FALSE),"ERROR")) -> 无 | AY11: =IF(AM11=0,"无",IFERROR(VLOOKUP(AM11,角色_装备!B:C,2,FALSE),"ERROR")) -> 无
E12: =IF(D12="","",IFERROR(VLOOKUP(D12,角色_种族_友方!B:C,2,FALSE),"ERROR")) | AB12: =IF(Y12="","",IFERROR(VLOOKUP(Y12,角色_能力!B:C,2,FALSE),"ERROR")) | AC12: =IF(Z12="","",IFERROR(VLOOKUP(Z12,角色_能力!B:C,2,FALSE),"ERROR")) | AQ12: =IF(AE12="","",IFERROR(VLOOKUP(AE12,角色_装备!B:C,2,FALSE),"ERROR")) | AR12: =IF(AF12="","",IFERROR(VLOOKUP(AF12,角色_装备!B:C,2,FALSE),"ERROR")) | AS12: =IF(AG12="","",IFERROR(VLOOKUP(AG12,角色_装备!B:C,2,FALSE),"ERROR")) | AW12: =IF(AK12="","",IFERROR(VLOOKUP(AK12,角色_装备!B:C,2,FALSE),"ERROR")) | AX12: =IF(AL12="","",IFERROR(VLOOKUP(AL12,角色_装备!B:C,2,FALSE),"ERROR")) | AY12: =IF(AM12="","",IFERROR(VLOOKUP(AM12,角色_装备!B:C,2,FALSE),"ERROR"))
E13: =IF(D13="","",IFERROR(VLOOKUP(D13,角色_种族_友方!B:C,2,FALSE),"ERROR")) | AB13: =IF(Y13="","",IFERROR(VLOOKUP(Y13,角色_能力!B:C,2,FALSE),"ERROR")) | AC13: =IF(Z13="","",IFERROR(VLOOKUP(Z13,角色_能力!B:C,2,FALSE),"ERROR")) | AQ13: =IF(AE13="","",IFERROR(VLOOKUP(AE13,角色_装备!B:C,2,FALSE),"ERROR")) | AR13: =IF(AF13="","",IFERROR(VLOOKUP(AF13,角色_装备!B:C,2,FALSE),"ERROR")) | AS13: =IF(AG13="","",IFERROR(VLOOKUP(AG13,角色_装备!B:C,2,FALSE),"ERROR")) | AW13: =IF(AK13="","",IFERROR(VLOOKUP(AK13,角色_装备!B:C,2,FALSE),"ERROR")) | AX13: =IF(AL13="","",IFERROR(VLOOKUP(AL13,角色_装备!B:C,2,FALSE),"ERROR")) | AY13: =IF(AM13="","",IFERROR(VLOOKUP(AM13,角色_装备!B:C,2,FALSE),"ERROR"))
E14: =IF(D14="","",IFERROR(VLOOKUP(D14,角色_种族_友方!B:C,2,FALSE),"ERROR")) | AB14: =IF(Y14="","",IFERROR(VLOOKUP(Y14,角色_能力!B:C,2,FALSE),"ERROR")) | AC14: =IF(Z14="","",IFERROR(VLOOKUP(Z14,角色_能力!B:C,2,FALSE),"ERROR")) | AQ14: =IF(AE14="","",IFERROR(VLOOKUP(AE14,角色_装备!B:C,2,FALSE),"ERROR")) | AR14: =IF(AF14="","",IFERROR(VLOOKUP(AF14,角色_装备!B:C,2,FALSE),"ERROR")) | AS14: =IF(AG14="","",IFERROR(VLOOKUP(AG14,角色_装备!B:C,2,FALSE),"ERROR")) | AW14: =IF(AK14="","",IFERROR(VLOOKUP(AK14,角色_装备!B:C,2,FALSE),"ERROR")) | AX14: =IF(AL14="","",IFERROR(VLOOKUP(AL14,角色_装备!B:C,2,FALSE),"ERROR")) | AY14: =IF(AM14="","",IFERROR(VLOOKUP(AM14,角色_装备!B:C,2,FALSE),"ERROR"))
E15: =IF(D15="","",IFERROR(VLOOKUP(D15,角色_种族_友方!B:C,2,FALSE),"ERROR")) | AB15: =IF(Y15="","",IFERROR(VLOOKUP(Y15,角色_能力!B:C,2,FALSE),"ERROR")) | AC15: =IF(Z15="","",IFERROR(VLOOKUP(Z15,角色_能力!B:C,2,FALSE),"ERROR")) | AQ15: =IF(AE15="","",IFERROR(VLOOKUP(AE15,角色_装备!B:C,2,FALSE),"ERROR")) | AR15: =IF(AF15="","",IFERROR(VLOOKUP(AF15,角色_装备!B:C,2,FALSE),"ERROR")) | AS15: =IF(AG15="","",IFERROR(VLOOKUP(AG15,角色_装备!B:C,2,FALSE),"ERROR")) | AW15: =IF(AK15="","",IFERROR(VLOOKUP(AK15,角色_装备!B:C,2,FALSE),"ERROR")) | AX15: =IF(AL15="","",IFERROR(VLOOKUP(AL15,角色_装备!B:C,2,FALSE),"ERROR")) | AY15: =IF(AM15="","",IFERROR(VLOOKUP(AM15,角色_装备!B:C,2,FALSE),"ERROR"))
E16: =IF(D16="","",IFERROR(VLOOKUP(D16,角色_种族_友方!B:C,2,FALSE),"ERROR")) | AB16: =IF(Y16="","",IFERROR(VLOOKUP(Y16,角色_能力!B:C,2,FALSE),"ERROR")) | AC16: =IF(Z16="","",IFERROR(VLOOKUP(Z16,角色_能力!B:C,2,FALSE),"ERROR")) | AQ16: =IF(AE16="","",IFERROR(VLOOKUP(AE16,角色_装备!B:C,2,FALSE),"ERROR")) | AR16: =IF(AF16="","",IFERROR(VLOOKUP(AF16,角色_装备!B:C,2,FALSE),"ERROR")) | AS16: =IF(AG16="","",IFERROR(VLOOKUP(AG16,角色_装备!B:C,2,FALSE),"ERROR")) | AW16: =IF(AK16="","",IFERROR(VLOOKUP(AK16,角色_装备!B:C,2,FALSE),"ERROR")) | AX16: =IF(AL16="","",IFERROR(VLOOKUP(AL16,角色_装备!B:C,2,FALSE),"ERROR")) | AY16: =IF(AM16="","",IFERROR(VLOOKUP(AM16,角色_装备!B:C,2,FALSE),"ERROR"))
E17: =IF(D17="","",IFERROR(VLOOKUP(D17,角色_种族_友方!B:C,2,FALSE),"ERROR")) | AB17: =IF(Y17="","",IFERROR(VLOOKUP(Y17,角色_能力!B:C,2,FALSE),"ERROR")) | AC17: =IF(Z17="","",IFERROR(VLOOKUP(Z17,角色_能力!B:C,2,FALSE),"ERROR")) | AQ17: =IF(AE17="","",IFERROR(VLOOKUP(AE17,角色_装备!B:C,2,FALSE),"ERROR")) | AR17: =IF(AF17="","",IFERROR(VLOOKUP(AF17,角色_装备!B:C,2,FALSE),"ERROR")) | AS17: =IF(AG17="","",IFERROR(VLOOKUP(AG17,角色_装备!B:C,2,FALSE),"ERROR")) | AW17: =IF(AK17="","",IFERROR(VLOOKUP(AK17,角色_装备!B:C,2,FALSE),"ERROR")) | AX17: =IF(AL17="","",IFERROR(VLOOKUP(AL17,角色_装备!B:C,2,FALSE),"ERROR")) | AY17: =IF(AM17="","",IFERROR(VLOOKUP(AM17,角色_装备!B:C,2,FALSE),"ERROR"))
E18: =IF(D18="","",IFERROR(VLOOKUP(D18,角色_种族_友方!B:C,2,FALSE),"ERROR")) | AB18: =IF(Y18="","",IFERROR(VLOOKUP(Y18,角色_能力!B:C,2,FALSE),"ERROR")) | AC18: =IF(Z18="","",IFERROR(VLOOKUP(Z18,角色_能力!B:C,2,FALSE),"ERROR")) | AQ18: =IF(AE18="","",IFERROR(VLOOKUP(AE18,角色_装备!B:C,2,FALSE),"ERROR")) | AR18: =IF(AF18="","",IFERROR(VLOOKUP(AF18,角色_装备!B:C,2,FALSE),"ERROR")) | AS18: =IF(AG18="","",IFERROR(VLOOKUP(AG18,角色_装备!B:C,2,FALSE),"ERROR")) | AW18: =IF(AK18="","",IFERROR(VLOOKUP(AK18,角色_装备!B:C,2,FALSE),"ERROR")) | AX18: =IF(AL18="","",IFERROR(VLOOKUP(AL18,角色_装备!B:C,2,FALSE),"ERROR")) | AY18: =IF(AM18="","",IFERROR(VLOOKUP(AM18,角色_装备!B:C,2,FALSE),"ERROR"))
E19: =IF(D19="","",IFERROR(VLOOKUP(D19,角色_种族_友方!B:C,2,FALSE),"ERROR")) | AB19: =IF(Y19="","",IFERROR(VLOOKUP(Y19,角色_能力!B:C,2,FALSE),"ERROR")) | AC19: =IF(Z19="","",IFERROR(VLOOKUP(Z19,角色_能力!B:C,2,FALSE),"ERROR")) | AQ19: =IF(AE19="","",IFERROR(VLOOKUP(AE19,角色_装备!B:C,2,FALSE),"ERROR")) | AR19: =IF(AF19="","",IFERROR(VLOOKUP(AF19,角色_装备!B:C,2,FALSE),"ERROR")) | AS19: =IF(AG19="","",IFERROR(VLOOKUP(AG19,角色_装备!B:C,2,FALSE),"ERROR")) | AW19: =IF(AK19="","",IFERROR(VLOOKUP(AK19,角色_装备!B:C,2,FALSE),"ERROR")) | AX19: =IF(AL19="","",IFERROR(VLOOKUP(AL19,角色_装备!B:C,2,FALSE),"ERROR")) | AY19: =IF(AM19="","",IFERROR(VLOOKUP(AM19,角色_装备!B:C,2,FALSE),"ERROR"))
E20: =IF(D20="","",IFERROR(VLOOKUP(D20,角色_种族_友方!B:C,2,FALSE),"ERROR")) | AB20: =IF(Y20="","",IFERROR(VLOOKUP(Y20,角色_能力!B:C,2,FALSE),"ERROR")) | AC20: =IF(Z20="","",IFERROR(VLOOKUP(Z20,角色_能力!B:C,2,FALSE),"ERROR")) | AQ20: =IF(AE20="","",IFERROR(VLOOKUP(AE20,角色_装备!B:C,2,FALSE),"ERROR")) | AR20: =IF(AF20="","",IFERROR(VLOOKUP(AF20,角色_装备!B:C,2,FALSE),"ERROR")) | AS20: =IF(AG20="","",IFERROR(VLOOKUP(AG20,角色_装备!B:C,2,FALSE),"ERROR")) | AW20: =IF(AK20="","",IFERROR(VLOOKUP(AK20,角色_装备!B:C,2,FALSE),"ERROR")) | AX20: =IF(AL20="","",IFERROR(VLOOKUP(AL20,角色_装备!B:C,2,FALSE),"ERROR")) | AY20: =IF(AM20="","",IFERROR(VLOOKUP(AM20,角色_装备!B:C,2,FALSE),"ERROR"))
E21: =IF(D21="","",IFERROR(VLOOKUP(D21,角色_种族_友方!B:C,2,FALSE),"ERROR")) | AB21: =IF(Y21="","",IFERROR(VLOOKUP(Y21,角色_能力!B:C,2,FALSE),"ERROR")) | AC21: =IF(Z21="","",IFERROR(VLOOKUP(Z21,角色_能力!B:C,2,FALSE),"ERROR")) | AQ21: =IF(AE21="","",IFERROR(VLOOKUP(AE21,角色_装备!B:C,2,FALSE),"ERROR")) | AR21: =IF(AF21="","",IFERROR(VLOOKUP(AF21,角色_装备!B:C,2,FALSE),"ERROR")) | AS21: =IF(AG21="","",IFERROR(VLOOKUP(AG21,角色_装备!B:C,2,FALSE),"ERROR")) | AW21: =IF(AK21="","",IFERROR(VLOOKUP(AK21,角色_装备!B:C,2,FALSE),"ERROR")) | AX21: =IF(AL21="","",IFERROR(VLOOKUP(AL21,角色_装备!B:C,2,FALSE),"ERROR")) | AY21: =IF(AM21="","",IFERROR(VLOOKUP(AM21,角色_装备!B:C,2,FALSE),"ERROR"))
E22: =IF(D22="","",IFERROR(VLOOKUP(D22,角色_种族_友方!B:C,2,FALSE),"ERROR")) | AB22: =IF(Y22="","",IFERROR(VLOOKUP(Y22,角色_能力!B:C,2,FALSE),"ERROR")) | AC22: =IF(Z22="","",IFERROR(VLOOKUP(Z22,角色_能力!B:C,2,FALSE),"ERROR")) | AQ22: =IF(AE22="","",IFERROR(VLOOKUP(AE22,角色_装备!B:C,2,FALSE),"ERROR")) | AR22: =IF(AF22="","",IFERROR(VLOOKUP(AF22,角色_装备!B:C,2,FALSE),"ERROR")) | AS22: =IF(AG22="","",IFERROR(VLOOKUP(AG22,角色_装备!B:C,2,FALSE),"ERROR")) | AW22: =IF(AK22="","",IFERROR(VLOOKUP(AK22,角色_装备!B:C,2,FALSE),"ERROR")) | AX22: =IF(AL22="","",IFERROR(VLOOKUP(AL22,角色_装备!B:C,2,FALSE),"ERROR")) | AY22: =IF(AM22="","",IFERROR(VLOOKUP(AM22,角色_装备!B:C,2,FALSE),"ERROR"))
E23: =IF(D23="","",IFERROR(VLOOKUP(D23,角色_种族_友方!B:C,2,FALSE),"ERROR")) | AB23: =IF(Y23="","",IFERROR(VLOOKUP(Y23,角色_能力!B:C,2,FALSE),"ERROR")) | AC23: =IF(Z23="","",IFERROR(VLOOKUP(Z23,角色_能力!B:C,2,FALSE),"ERROR")) | AQ23: =IF(AE23="","",IFERROR(VLOOKUP(AE23,角色_装备!B:C,2,FALSE),"ERROR")) | AR23: =IF(AF23="","",IFERROR(VLOOKUP(AF23,角色_装备!B:C,2,FALSE),"ERROR")) | AS23: =IF(AG23="","",IFERROR(VLOOKUP(AG23,角色_装备!B:C,2,FALSE),"ERROR")) | AW23: =IF(AK23="","",IFERROR(VLOOKUP(AK23,角色_装备!B:C,2,FALSE),"ERROR")) | AX23: =IF(AL23="","",IFERROR(VLOOKUP(AL23,角色_装备!B:C,2,FALSE),"ERROR")) | AY23: =IF(AM23="","",IFERROR(VLOOKUP(AM23,角色_装备!B:C,2,FALSE),"ERROR"))
... E33: =IF(D33="","",IFERROR(VLOOKUP(D33,角色_种族_友方!B:C,2,FALSE),"ERROR")) | AB33: =IF(Y33="","",IFERROR(VLOOKUP(Y33,角色_能力!B:C,2,FALSE),"ERROR")) | AC33: =IF(Z33="","",IFERROR(VLOOKUP(Z33,角色_能力!B:C,2,FALSE),"ERROR")) | AQ33: =IF(AE33="","",IFERROR(VLOOKUP(AE33,角色_装备!B:C,2,FALSE),"ERROR")) | AR33: =IF(AF33="","",IFERROR(VLOOKUP(AF33,角色_装备!B:C,2,FALSE),"ERROR")) | AS33: =IF(AG33="","",IFERROR(VLOOKUP(AG33,角色_装备!B:C,2,FALSE),"ERROR")) | AW33: =IF(AK33="","",IFERROR(VLOOKUP(AK33,角色_装备!B:C,2,FALSE),"ERROR")) | AX33: =IF(AL33="","",IFERROR(VLOOKUP(AL33,角色_装备!B:C,2,FALSE),"ERROR")) | AY33: =IF(AM33="","",IFERROR(VLOOKUP(AM33,角色_装备!B:C,2,FALSE),"ERROR"))
E34: =IF(D34="","",IFERROR(VLOOKUP(D34,角色_种族_友方!B:C,2,FALSE),"ERROR")) | AB34: =IF(Y34="","",IFERROR(VLOOKUP(Y34,角色_能力!B:C,2,FALSE),"ERROR")) | AC34: =IF(Z34="","",IFERROR(VLOOKUP(Z34,角色_能力!B:C,2,FALSE),"ERROR")) | AQ34: =IF(AE34="","",IFERROR(VLOOKUP(AE34,角色_装备!B:C,2,FALSE),"ERROR")) | AR34: =IF(AF34="","",IFERROR(VLOOKUP(AF34,角色_装备!B:C,2,FALSE),"ERROR")) | AS34: =IF(AG34="","",IFERROR(VLOOKUP(AG34,角色_装备!B:C,2,FALSE),"ERROR")) | AX34: =IF(AL34="","",IFERROR(VLOOKUP(AL34,角色_装备!B:C,2,FALSE),"ERROR")) | AY34: =IF(AM34="","",IFERROR(VLOOKUP(AM34,角色_装备!B:C,2,FALSE),"ERROR"))
E35: =IF(D35="","",IFERROR(VLOOKUP(D35,角色_种族_友方!B:C,2,FALSE),"ERROR")) | AB35: =IF(Y35="","",IFERROR(VLOOKUP(Y35,角色_能力!B:C,2,FALSE),"ERROR")) | AC35: =IF(Z35="","",IFERROR(VLOOKUP(Z35,角色_能力!B:C,2,FALSE),"ERROR")) | AQ35: =IF(AE35="","",IFERROR(VLOOKUP(AE35,角色_装备!B:C,2,FALSE),"ERROR")) | AR35: =IF(AF35="","",IFERROR(VLOOKUP(AF35,角色_装备!B:C,2,FALSE),"ERROR")) | AS35: =IF(AG35="","",IFERROR(VLOOKUP(AG35,角色_装备!B:C,2,FALSE),"ERROR")) | AX35: =IF(AL35="","",IFERROR(VLOOKUP(AL35,角色_装备!B:C,2,FALSE),"ERROR")) | AY35: =IF(AM35="","",IFERROR(VLOOKUP(AM35,角色_装备!B:C,2,FALSE),"ERROR"))
E36: =IF(D36="","",IFERROR(VLOOKUP(D36,角色_种族_友方!B:C,2,FALSE),"ERROR")) | AB36: =IF(Y36="","",IFERROR(VLOOKUP(Y36,角色_能力!B:C,2,FALSE),"ERROR")) | AC36: =IF(Z36="","",IFERROR(VLOOKUP(Z36,角色_能力!B:C,2,FALSE),"ERROR")) | AQ36: =IF(AE36="","",IFERROR(VLOOKUP(AE36,角色_装备!B:C,2,FALSE),"ERROR")) | AR36: =IF(AF36="","",IFERROR(VLOOKUP(AF36,角色_装备!B:C,2,FALSE),"ERROR")) | AS36: =IF(AG36="","",IFERROR(VLOOKUP(AG36,角色_装备!B:C,2,FALSE),"ERROR")) | AX36: =IF(AL36="","",IFERROR(VLOOKUP(AL36,角色_装备!B:C,2,FALSE),"ERROR")) | AY36: =IF(AM36="","",IFERROR(VLOOKUP(AM36,角色_装备!B:C,2,FALSE),"ERROR"))
E37: =IF(D37="","",IFERROR(VLOOKUP(D37,角色_种族_友方!B:C,2,FALSE),"ERROR")) | AB37: =IF(Y37="","",IFERROR(VLOOKUP(Y37,角色_能力!B:C,2,FALSE),"ERROR")) | AC37: =IF(Z37="","",IFERROR(VLOOKUP(Z37,角色_能力!B:C,2,FALSE),"ERROR")) | AQ37: =IF(AE37="","",IFERROR(VLOOKUP(AE37,角色_装备!B:C,2,FALSE),"ERROR")) | AR37: =IF(AF37="","",IFERROR(VLOOKUP(AF37,角色_装备!B:C,2,FALSE),"ERROR")) | AS37: =IF(AG37="","",IFERROR(VLOOKUP(AG37,角色_装备!B:C,2,FALSE),"ERROR")) | AX37: =IF(AL37="","",IFERROR(VLOOKUP(AL37,角色_装备!B:C,2,FALSE),"ERROR")) | AY37: =IF(AM37="","",IFERROR(VLOOKUP(AM37,角色_装备!B:C,2,FALSE),"ERROR"))
E38: =IF(D38="","",IFERROR(VLOOKUP(D38,角色_种族_友方!B:C,2,FALSE),"ERROR")) | AB38: =IF(Y38="","",IFERROR(VLOOKUP(Y38,角色_能力!B:C,2,FALSE),"ERROR")) | AC38: =IF(Z38="","",IFERROR(VLOOKUP(Z38,角色_能力!B:C,2,FALSE),"ERROR")) | AQ38: =IF(AE38="","",IFERROR(VLOOKUP(AE38,角色_装备!B:C,2,FALSE),"ERROR")) | AR38: =IF(AF38="","",IFERROR(VLOOKUP(AF38,角色_装备!B:C,2,FALSE),"ERROR")) | AS38: =IF(AG38="","",IFERROR(VLOOKUP(AG38,角色_装备!B:C,2,FALSE),"ERROR")) | AX38: =IF(AL38="","",IFERROR(VLOOKUP(AL38,角色_装备!B:C,2,FALSE),"ERROR")) | AY38: =IF(AM38="","",IFERROR(VLOOKUP(AM38,角色_装备!B:C,2,FALSE),"ERROR"))
E39: =IF(D39="","",IFERROR(VLOOKUP(D39,角色_种族_友方!B:C,2,FALSE),"ERROR")) | AB39: =IF(Y39="","",IFERROR(VLOOKUP(Y39,角色_能力!B:C,2,FALSE),"ERROR")) | AC39: =IF(Z39="","",IFERROR(VLOOKUP(Z39,角色_能力!B:C,2,FALSE),"ERROR")) | AQ39: =IF(AE39="","",IFERROR(VLOOKUP(AE39,角色_装备!B:C,2,FALSE),"ERROR")) | AR39: =IF(AF39="","",IFERROR(VLOOKUP(AF39,角色_装备!B:C,2,FALSE),"ERROR")) | AS39: =IF(AG39="","",IFERROR(VLOOKUP(AG39,角色_装备!B:C,2,FALSE),"ERROR")) | AY39: =IF(AM39="","",IFERROR(VLOOKUP(AM39,角色_装备!B:C,2,FALSE),"ERROR"))
E40: =IF(D40="","",IFERROR(VLOOKUP(D40,角色_种族_友方!B:C,2,FALSE),"ERROR")) | AB40: =IF(Y40="","",IFERROR(VLOOKUP(Y40,角色_能力!B:C,2,FALSE),"ERROR")) | AC40: =IF(Z40="","",IFERROR(VLOOKUP(Z40,角色_能力!B:C,2,FALSE),"ERROR")) | AQ40: =IF(AE40="","",IFERROR(VLOOKUP(AE40,角色_装备!B:C,2,FALSE),"ERROR")) | AR40: =IF(AF40="","",IFERROR(VLOOKUP(AF40,角色_装备!B:C,2,FALSE),"ERROR")) | AS40: =IF(AG40="","",IFERROR(VLOOKUP(AG40,角色_装备!B:C,2,FALSE),"ERROR")) | AY40: =IF(AM40="","",IFERROR(VLOOKUP(AM40,角色_装备!B:C,2,FALSE),"ERROR"))
E41: =IF(D41="","",IFERROR(VLOOKUP(D41,角色_种族_友方!B:C,2,FALSE),"ERROR")) | AB41: =IF(Y41="","",IFERROR(VLOOKUP(Y41,角色_能力!B:C,2,FALSE),"ERROR")) | AC41: =IF(Z41="","",IFERROR(VLOOKUP(Z41,角色_能力!B:C,2,FALSE),"ERROR")) | AQ41: =IF(AE41="","",IFERROR(VLOOKUP(AE41,角色_装备!B:C,2,FALSE),"ERROR")) | AR41: =IF(AF41="","",IFERROR(VLOOKUP(AF41,角色_装备!B:C,2,FALSE),"ERROR")) | AS41: =IF(AG41="","",IFERROR(VLOOKUP(AG41,角色_装备!B:C,2,FALSE),"ERROR"))
E42: =IF(D42="","",IFERROR(VLOOKUP(D42,角色_种族_友方!B:C,2,FALSE),"ERROR")) | AB42: =IF(Y42="","",IFERROR(VLOOKUP(Y42,角色_能力!B:C,2,FALSE),"ERROR")) | AC42: =IF(Z42="","",IFERROR(VLOOKUP(Z42,角色_能力!B:C,2,FALSE),"ERROR")) | AQ42: =IF(AE42="","",IFERROR(VLOOKUP(AE42,角色_装备!B:C,2,FALSE),"ERROR")) | AR42: =IF(AF42="","",IFERROR(VLOOKUP(AF42,角色_装备!B:C,2,FALSE),"ERROR")) | AS42: =IF(AG42="","",IFERROR(VLOOKUP(AG42,角色_装备!B:C,2,FALSE),"ERROR"))
E43: =IF(D43="","",IFERROR(VLOOKUP(D43,角色_种族_友方!B:C,2,FALSE),"ERROR")) | AB43: =IF(Y43="","",IFERROR(VLOOKUP(Y43,角色_能力!B:C,2,FALSE),"ERROR")) | AC43: =IF(Z43="","",IFERROR(VLOOKUP(Z43,角色_能力!B:C,2,FALSE),"ERROR")) | AQ43: =IF(AE43="","",IFERROR(VLOOKUP(AE43,角色_装备!B:C,2,FALSE),"ERROR")) | AR43: =IF(AF43="","",IFERROR(VLOOKUP(AF43,角色_装备!B:C,2,FALSE),"ERROR")) | AS43: =IF(AG43="","",IFERROR(VLOOKUP(AG43,角色_装备!B:C,2,FALSE),"ERROR"))
E44: =IF(D44="","",IFERROR(VLOOKUP(D44,角色_种族_友方!B:C,2,FALSE),"ERROR")) | AB44: =IF(Y44="","",IFERROR(VLOOKUP(Y44,角色_能力!B:C,2,FALSE),"ERROR")) | AC44: =IF(Z44="","",IFERROR(VLOOKUP(Z44,角色_能力!B:C,2,FALSE),"ERROR")) | AQ44: =IF(AE44="","",IFERROR(VLOOKUP(AE44,角色_装备!B:C,2,FALSE),"ERROR")) | AR44: =IF(AF44="","",IFERROR(VLOOKUP(AF44,角色_装备!B:C,2,FALSE),"ERROR")) | AS44: =IF(AG44="","",IFERROR(VLOOKUP(AG44,角色_装备!B:C,2,FALSE),"ERROR"))
E45: =IF(D45="","",IFERROR(VLOOKUP(D45,角色_种族_友方!B:C,2,FALSE),"ERROR")) | AB45: =IF(Y45="","",IFERROR(VLOOKUP(Y45,角色_能力!B:C,2,FALSE),"ERROR")) | AC45: =IF(Z45="","",IFERROR(VLOOKUP(Z45,角色_能力!B:C,2,FALSE),"ERROR")) | AQ45: =IF(AE45="","",IFERROR(VLOOKUP(AE45,角色_装备!B:C,2,FALSE),"ERROR")) | AR45: =IF(AF45="","",IFERROR(VLOOKUP(AF45,角色_装备!B:C,2,FALSE),"ERROR")) | AS45: =IF(AG45="","",IFERROR(VLOOKUP(AG45,角色_装备!B:C,2,FALSE),"ERROR"))
E46: =IF(D46="","",IFERROR(VLOOKUP(D46,角色_种族_友方!B:C,2,FALSE),"ERROR")) | AB46: =IF(Y46="","",IFERROR(VLOOKUP(Y46,角色_能力!B:C,2,FALSE),"ERROR")) | AC46: =IF(Z46="","",IFERROR(VLOOKUP(Z46,角色_能力!B:C,2,FALSE),"ERROR")) | AQ46: =IF(AE46="","",IFERROR(VLOOKUP(AE46,角色_装备!B:C,2,FALSE),"ERROR")) | AR46: =IF(AF46="","",IFERROR(VLOOKUP(AF46,角色_装备!B:C,2,FALSE),"ERROR")) | AS46: =IF(AG46="","",IFERROR(VLOOKUP(AG46,角色_装备!B:C,2,FALSE),"ERROR"))
E47: =IF(D47="","",IFERROR(VLOOKUP(D47,角色_种族_友方!B:C,2,FALSE),"ERROR")) | AB47: =IF(Y47="","",IFERROR(VLOOKUP(Y47,角色_能力!B:C,2,FALSE),"ERROR")) | AQ47: =IF(AE47="","",IFERROR(VLOOKUP(AE47,角色_装备!B:C,2,FALSE),"ERROR")) | AR47: =IF(AF47="","",IFERROR(VLOOKUP(AF47,角色_装备!B:C,2,FALSE),"ERROR")) | AS47: =IF(AG47="","",IFERROR(VLOOKUP(AG47,角色_装备!B:C,2,FALSE),"ERROR"))
E48: =IF(D48="","",IFERROR(VLOOKUP(D48,角色_种族_友方!B:C,2,FALSE),"ERROR")) | AB48: =IF(Y48="","",IFERROR(VLOOKUP(Y48,角色_能力!B:C,2,FALSE),"ERROR")) | AQ48: =IF(AE48="","",IFERROR(VLOOKUP(AE48,角色_装备!B:C,2,FALSE),"ERROR")) | AR48: =IF(AF48="","",IFERROR(VLOOKUP(AF48,角色_装备!B:C,2,FALSE),"ERROR")) | AS48: =IF(AG48="","",IFERROR(VLOOKUP(AG48,角色_装备!B:C,2,FALSE),"ERROR"))
E49: =IF(D49="","",IFERROR(VLOOKUP(D49,角色_种族_友方!B:C,2,FALSE),"ERROR")) | AB49: =IF(Y49="","",IFERROR(VLOOKUP(Y49,角色_能力!B:C,2,FALSE),"ERROR")) | AQ49: =IF(AE49="","",IFERROR(VLOOKUP(AE49,角色_装备!B:C,2,FALSE),"ERROR")) | AR49: =IF(AF49="","",IFERROR(VLOOKUP(AF49,角色_装备!B:C,2,FALSE),"ERROR")) | AS49: =IF(AG49="","",IFERROR(VLOOKUP(AG49,角色_装备!B:C,2,FALSE),"ERROR"))
...

Sheet 角色_种族_敌方
A1: ##var | B1: id | C1: name | D1: race | E1: creature_type | F1: body_type | G1: proficiency | H1: attribute_preset | T1: ##能力表索引
A2: ##type | B2: int | C2: string | D2: GameActor.EmRace | E2: GameActor.EmCreatureType | F2: GameActor.EmBodyType | G2: GameActor.EmEquipType | H2: GameActor.AttributePreset
A3: ##type | H3: abilityScores | N3: resistance | O3: armourClass | P3: movement | Q3: initiative | R3: abilities
A4: ##type | H4: Strength | I4: Dexterity | J4: Constitution | K4: Intelligent | L4: Wisdom | M4: Charisma
A5: ## | B5: 唯一id | C5: 名称 | D5: 种族 | E5: 类别 | F5: 体型 | G5: 装备熟练 | H5: 力量 | I5: 敏捷 | J5: 体质 | K5: 智力 | L5: 感知 | M5: 魅力 | N5: 伤害抗性 | O5: 护甲等级 | P5: 移动力 | Q5: 先攻 | R5: 能力表
B6: 31001 | C6: 地精 | D6: 地精 | E6: 类人 | F6: 小型 | H6: 0 | I6: 0 | J6: 0 | K6: 0 | L6: 0 | M6: 0 | N6: 无&0 | O6: 0 | P6: 0 | Q6: 0 | T6: =IF(R6="","",IFERROR(VLOOKUP(R6,角色_能力!B:C,2,FALSE),"ERROR")) | U6: =IF(S6="","",IFERROR(VLOOKUP(S6,角色_能力!B:C,2,FALSE),"ERROR"))
B7: 31002 | C7: 类地精 | D7: 地精 | E7: 类人 | F7: 中型 | H7: 0 | I7: 0 | J7: 0 | K7: 0 | L7: 0 | M7: 0 | N7: 无&0 | O7: 0 | P7: 0 | Q7: 0

Sheet 角色_预设_敌方
A1: ##var | B1: id | C1: name | D1: subrace | E1: ##亚种索引 | F1: level | G1: clasz | K1: expOnKilled | L1: max_hp | O1: attribute_preset | AB1: ##能力表索引 | AE1: item_preset1 | AK1: item_preset2 | AQ1: ##道具预设id索引 | BC1: knapsack_items
A2: ##type | B2: int | C2: string | D2: int#ref=GameActor.TbSubrace | F2: int | G2: map,GameActor.EmClass,int | K2: int | L2: GameActor.MaxHp | O2: GameActor.AttributePreset | AE2: GameActor.ActorItemPreset | AK2: GameActor.ActorItemPreset | BC2: map,(int#ref=GameActor.TbItem),float
A3: ##type | L3: $type | O3: abilityScores | U3: resistance | V3: armourClass | W3: movement | X3: initiative | Y3: abilities
A4: ##type | O4: Strength | P4: Dexterity | Q4: Constitution | R4: Intelligent | S4: Wisdom | T4: Charisma | AE4: MainHand | AF4: OffHand | AG4: Body | AH4: Artifacts | AK4: MainHand | AL4: OffHand | AM4: Body | AN4: Artifacts
A5: ## | B5: 唯一id | C5: 名称 | D5: 亚种 | F5: 角色等级 | G5: 职业 | H5: 等级 | I5: 职业 | J5: 等级 | K5: 击杀经验 | L5: 生命值类型 | M5: 加成 | O5: 力量 | P5: 敏捷 | Q5: 体质 | R5: 智力 | S5: 感知 | T5: 魅力 | U5: 伤害抗性 | V5: 护甲等级 | W5: 移动力 | X5: 先攻 | Y5: 能力表 | AE5: 主手装备 | AF5: 副手装备 | AG5: 身体装备 | AH5: 奇物 | AK5: 主手装备 | AL5: 副手装备 | AM5: 身体装备 | AN5: 奇物 | AQ5: 主手装备 | AR5: 副手装备 | AS5: 身体装备 | AT5: 奇物 | AW5: 主手装备 | AX5: 副手装备 | AY5: 身体装备 | AZ5: 奇物 | BC5: 道具id | BD5: 出现概率 | BE5: 道具id | BF5: 出现概率 | BG5: 道具id | BH5: 出现概率
B6: 65001 | C6: 地精盾刀手 | D6: 31001 | E6: =IF(D6="","",IFERROR(VLOOKUP(D6,角色_种族_敌方!B:C,2,FALSE),"ERROR")) -> 地精 | F6: =H6+J6 -> 1 | G6: 战士 | H6: 1 | K6: 50 | L6: 骰子生命值 | M6: 2&6 | N6: 0 | O6: 8 | P6: 14 | Q6: 10 | R6: 10 | S6: 8 | T6: 8 | U6: 无&0 | V6: 15 | W6: 5 | X6: 2 | AE6: 41201 | AF6: 40501 | AG6: 40201 | AK6: 40701 | AL6: 40501 | AM6: 40201 | AQ6: =IF(AE6=0,"无",IFERROR(VLOOKUP(AE6,角色_装备!B:C,2,FALSE),"ERROR")) -> 镰刀 | AR6: =IF(AF6=0,"无",IFERROR(VLOOKUP(AF6,角色_装备!B:C,2,FALSE),"ERROR")) -> 盾牌 | AS6: =IF(AG6=0,"无",IFERROR(VLOOKUP(AG6,角色_装备!B:C,2,FALSE),"ERROR")) -> 布甲 | AW6: =IF(AK6=0,"无",IFERROR(VLOOKUP(AK6,角色_装备!B:C,2,FALSE),"ERROR")) -> 匕首 | AX6: =IF(AL6=0,"无",IFERROR(VLOOKUP(AL6,角色_装备!B:C,2,FALSE),"ERROR")) -> 盾牌 | AY6: =IF(AM6=0,"无",IFERROR(VLOOKUP(AM6,角色_装备!B:C,2,FALSE),"ERROR")) -> 布甲
B7: 65002 | C7: 地精长矛手 | D7: 31001 | E7: =IF(D7="","",IFERROR(VLOOKUP(D7,角色_种族_敌方!B:C,2,FALSE),"ERROR")) -> 地精 | F7: =H7+J7 -> 1 | G7: 战士 | H7: 1 | K7: 50 | L7: 骰子生命值 | M7: 2&6 | N7: 0 | O7: 8 | P7: 14 | Q7: 10 | R7: 10 | S7: 8 | T7: 8 | U7: 无&0 | V7: 13 | W7: 5 | X7: 2 | AE7: 41301 | AF7: 0 | AG7: 40201 | AK7: 41101 | AL7: 0 | AM7: 40201 | AQ7: =IF(AE7=0,"无",IFERROR(VLOOKUP(AE7,角色_装备!B:C,2,FALSE),"ERROR")) -> 矛 | AR7: =IF(AF7=0,"无",IFERROR(VLOOKUP(AF7,角色_装备!B:C,2,FALSE),"ERROR")) -> 无 | AS7: =IF(AG7=0,"无",IFERROR(VLOOKUP(AG7,角色_装备!B:C,2,FALSE),"ERROR")) -> 布甲 | AW7: =IF(AK7=0,"无",IFERROR(VLOOKUP(AK7,角色_装备!B:C,2,FALSE),"ERROR")) -> 长棍 | AX7: =IF(AL7=0,"无",IFERROR(VLOOKUP(AL7,角色_装备!B:C,2,FALSE),"ERROR")) -> 无 | AY7: =IF(AM7=0,"无",IFERROR(VLOOKUP(AM7,角色_装备!B:C,2,FALSE),"ERROR")) -> 布甲
B8: 65003 | C8: 地精弓箭手 | D8: 31001 | E8: =IF(D8="","",IFERROR(VLOOKUP(D8,角色_种族_敌方!B:C,2,FALSE),"ERROR")) -> 地精 | F8: =H8+J8 -> 1 | G8: 游侠 | H8: 1 | K8: 50 | L8: 骰子生命值 | M8: 2&6 | N8: 0 | O8: 8 | P8: 14 | Q8: 10 | R8: 10 | S8: 8 | T8: 8 | U8: 无&0 | V8: 12 | W8: 5 | X8: 2 | AE8: 41601 | AF8: 0 | AG8: 0 | AK8: 41501 | AL8: 0 | AM8: 0 | AQ8: =IF(AE8=0,"无",IFERROR(VLOOKUP(AE8,角色_装备!B:C,2,FALSE),"ERROR")) -> 短弓 | AR8: =IF(AF8=0,"无",IFERROR(VLOOKUP(AF8,角色_装备!B:C,2,FALSE),"ERROR")) -> 无 | AS8: =IF(AG8=0,"无",IFERROR(VLOOKUP(AG8,角色_装备!B:C,2,FALSE),"ERROR")) -> 无 | AW8: =IF(AK8=0,"无",IFERROR(VLOOKUP(AK8,角色_装备!B:C,2,FALSE),"ERROR")) -> 飞镖 | AX8: =IF(AL8=0,"无",IFERROR(VLOOKUP(AL8,角色_装备!B:C,2,FALSE),"ERROR")) -> 无 | AY8: =IF(AM8=0,"无",IFERROR(VLOOKUP(AM8,角色_装备!B:C,2,FALSE),"ERROR")) -> 无
B9: 65004 | C9: 地精双刀手 | D9: 31001 | E9: =IF(D9="","",IFERROR(VLOOKUP(D9,角色_种族_敌方!B:C,2,FALSE),"ERROR")) -> 地精 | F9: =H9+J9 -> 1 | G9: 游荡者 | H9: 1 | K9: 50 | L9: 骰子生命值 | M9: 2&6 | N9: 0 | O9: 8 | P9: 14 | Q9: 10 | R9: 10 | S9: 8 | T9: 8 | U9: 无&0 | V9: 13 | W9: 5 | X9: 2 | AE9: 42501 | AF9: 40701 | AG9: 40201 | AK9: 42501 | AL9: 41201 | AM9: 40201 | AQ9: =IF(AE9=0,"无",IFERROR(VLOOKUP(AE9,角色_装备!B:C,2,FALSE),"ERROR")) -> 弯刀 | AR9: =IF(AF9=0,"无",IFERROR(VLOOKUP(AF9,角色_装备!B:C,2,FALSE),"ERROR")) -> 匕首 | AS9: =IF(AG9=0,"无",IFERROR(VLOOKUP(AG9,角色_装备!B:C,2,FALSE),"ERROR")) -> 布甲 | AW9: =IF(AK9=0,"无",IFERROR(VLOOKUP(AK9,角色_装备!B:C,2,FALSE),"ERROR")) -> 弯刀 | AX9: =IF(AL9=0,"无",IFERROR(VLOOKUP(AL9,角色_装备!B:C,2,FALSE),"ERROR")) -> 镰刀 | AY9: =IF(AM9=0,"无",IFERROR(VLOOKUP(AM9,角色_装备!B:C,2,FALSE),"ERROR")) -> 布甲
B10: 65005 | C10: 地精军阀 | D10: 31001 | E10: =IF(D10="","",IFERROR(VLOOKUP(D10,角色_种族_敌方!B:C,2,FALSE),"ERROR")) -> 地精 | F10: =H10+J10 -> 4 | G10: 战士 | H10: 4 | K10: 200 | L10: 骰子生命值 | M10: 6&6 | N10: 0 | O10: 10 | P10: 14 | Q10: 10 | R10: 10 | S10: 8 | T10: 10 | U10: 无&0 | V10: 18 | W10: 5 | X10: 2 | AE10: 42501 | AF10: 40501 | AG10: 40402 | AK10: 41701 | AL10: 40501 | AM10: 40402 | AQ10: =IF(AE10=0,"无",IFERROR(VLOOKUP(AE10,角色_装备!B:C,2,FALSE),"ERROR")) -> 弯刀 | AR10: =IF(AF10=0,"无",IFERROR(VLOOKUP(AF10,角色_装备!B:C,2,FALSE),"ERROR")) -> 盾牌 | AS10: =IF(AG10=0,"无",IFERROR(VLOOKUP(AG10,角色_装备!B:C,2,FALSE),"ERROR")) -> 链甲 | AW10: =IF(AK10=0,"无",IFERROR(VLOOKUP(AK10,角色_装备!B:C,2,FALSE),"ERROR")) -> 战斧 | AX10: =IF(AL10=0,"无",IFERROR(VLOOKUP(AL10,角色_装备!B:C,2,FALSE),"ERROR")) -> 盾牌 | AY10: =IF(AM10=0,"无",IFERROR(VLOOKUP(AM10,角色_装备!B:C,2,FALSE),"ERROR")) -> 链甲
B11: 65006 | C11: 熊地精 | D11: 31002 | E11: =IF(D11="","",IFERROR(VLOOKUP(D11,角色_种族_敌方!B:C,2,FALSE),"ERROR")) -> 类地精 | F11: =H11+J11 -> 3 | G11: 战士 | H11: 3 | K11: 700 | L11: 骰子生命值 | M11: 5&8 | N11: 0 | O11: 17 | P11: 14 | Q11: 14 | R11: 8 | S11: 12 | T11: 11 | U11: 无&0 | V11: 14 | W11: 6 | X11: 2 | Y11: 50018 | AE11: 42201 | AF11: 0 | AG11: 40402 | AK11: 42201 | AL11: 0 | AM11: 40401 | AQ11: =IF(AE11=0,"无",IFERROR(VLOOKUP(AE11,角色_装备!B:C,2,FALSE),"ERROR")) -> 巨锤 | AR11: =IF(AF11=0,"无",IFERROR(VLOOKUP(AF11,角色_装备!B:C,2,FALSE),"ERROR")) -> 无 | AS11: =IF(AG11=0,"无",IFERROR(VLOOKUP(AG11,角色_装备!B:C,2,FALSE),"ERROR")) -> 链甲 | AW11: =IF(AK11=0,"无",IFERROR(VLOOKUP(AK11,角色_装备!B:C,2,FALSE),"ERROR")) -> 巨锤 | AX11: =IF(AL11=0,"无",IFERROR(VLOOKUP(AL11,角色_装备!B:C,2,FALSE),"ERROR")) -> 无 | AY11: =IF(AM11=0,"无",IFERROR(VLOOKUP(AM11,角色_装备!B:C,2,FALSE),"ERROR")) -> 环甲
E13: =IF(D13="","",IFERROR(VLOOKUP(D13,角色_种族_友方!B:C,2,FALSE),"ERROR")) | AB13: =IF(Y13="","",IFERROR(VLOOKUP(Y13,角色_能力!B:C,2,FALSE),"ERROR")) | AC13: =IF(Z13="","",IFERROR(VLOOKUP(Z13,角色_能力!B:C,2,FALSE),"ERROR")) | AQ13: =IF(AE13="","",IFERROR(VLOOKUP(AE13,角色_装备!B:C,2,FALSE),"ERROR")) | AR13: =IF(AF13="","",IFERROR(VLOOKUP(AF13,角色_装备!B:C,2,FALSE),"ERROR")) | AS13: =IF(AG13="","",IFERROR(VLOOKUP(AG13,角色_装备!B:C,2,FALSE),"ERROR")) | AW13: =IF(AK13="","",IFERROR(VLOOKUP(AK13,角色_装备!B:C,2,FALSE),"ERROR")) | AX13: =IF(AL13="","",IFERROR(VLOOKUP(AL13,角色_装备!B:C,2,FALSE),"ERROR")) | AY13: =IF(AM13="","",IFERROR(VLOOKUP(AM13,角色_装备!B:C,2,FALSE),"ERROR"))
E14: =IF(D14="","",IFERROR(VLOOKUP(D14,角色_种族_友方!B:C,2,FALSE),"ERROR")) | AB14: =IF(Y14="","",IFERROR(VLOOKUP(Y14,角色_能力!B:C,2,FALSE),"ERROR")) | AC14: =IF(Z14="","",IFERROR(VLOOKUP(Z14,角色_能力!B:C,2,FALSE),"ERROR")) | AQ14: =IF(AE14="","",IFERROR(VLOOKUP(AE14,角色_装备!B:C,2,FALSE),"ERROR")) | AR14: =IF(AF14="","",IFERROR(VLOOKUP(AF14,角色_装备!B:C,2,FALSE),"ERROR")) | AS14: =IF(AG14="","",IFERROR(VLOOKUP(AG14,角色_装备!B:C,2,FALSE),"ERROR")) | AW14: =IF(AK14="","",IFERROR(VLOOKUP(AK14,角色_装备!B:C,2,FALSE),"ERROR")) | AX14: =IF(AL14="","",IFERROR(VLOOKUP(AL14,角色_装备!B:C,2,FALSE),"ERROR")) | AY14: =IF(AM14="","",IFERROR(VLOOKUP(AM14,角色_装备!B:C,2,FALSE),"ERROR"))
E15: =IF(D15="","",IFERROR(VLOOKUP(D15,角色_种族_友方!B:C,2,FALSE),"ERROR")) | AB15: =IF(Y15="","",IFERROR(VLOOKUP(Y15,角色_能力!B:C,2,FALSE),"ERROR")) | AC15: =IF(Z15="","",IFERROR(VLOOKUP(Z15,角色_能力!B:C,2,FALSE),"ERROR")) | AQ15: =IF(AE15="","",IFERROR(VLOOKUP(AE15,角色_装备!B:C,2,FALSE),"ERROR")) | AR15: =IF(AF15="","",IFERROR(VLOOKUP(AF15,角色_装备!B:C,2,FALSE),"ERROR")) | AS15: =IF(AG15="","",IFERROR(VLOOKUP(AG15,角色_装备!B:C,2,FALSE),"ERROR")) | AW15: =IF(AK15="","",IFERROR(VLOOKUP(AK15,角色_装备!B:C,2,FALSE),"ERROR")) | AX15: =IF(AL15="","",IFERROR(VLOOKUP(AL15,角色_装备!B:C,2,FALSE),"ERROR")) | AY15: =IF(AM15="","",IFERROR(VLOOKUP(AM15,角色_装备!B:C,2,FALSE),"ERROR"))
E16: =IF(D16="","",IFERROR(VLOOKUP(D16,角色_种族_友方!B:C,2,FALSE),"ERROR")) | AB16: =IF(Y16="","",IFERROR(VLOOKUP(Y16,角色_能力!B:C,2,FALSE),"ERROR")) | AC16: =IF(Z16="","",IFERROR(VLOOKUP(Z16,角色_能力!B:C,2,FALSE),"ERROR")) | AQ16: =IF(AE16="","",IFERROR(VLOOKUP(AE16,角色_装备!B:C,2,FALSE),"ERROR")) | AR16: =IF(AF16="","",IFERROR(VLOOKUP(AF16,角色_装备!B:C,2,FALSE),"ERROR")) | AS16: =IF(AG16="","",IFERROR(VLOOKUP(AG16,角色_装备!B:C,2,FALSE),"ERROR")) | AW16: =IF(AK16="","",IFERROR(VLOOKUP(AK16,角色_装备!B:C,2,FALSE),"ERROR")) | AX16: =IF(AL16="","",IFERROR(VLOOKUP(AL16,角色_装备!B:C,2,FALSE),"ERROR")) | AY16: =IF(AM16="","",IFERROR(VLOOKUP(AM16,角色_装备!B:C,2,FALSE),"ERROR"))
E17: =IF(D17="","",IFERROR(VLOOKUP(D17,角色_种族_友方!B:C,2,FALSE),"ERROR")) | AB17: =IF(Y17="","",IFERROR(VLOOKUP(Y17,角色_能力!B:C,2,FALSE),"ERROR")) | AC17: =IF(Z17="","",IFERROR(VLOOKUP(Z17,角色_能力!B:C,2,FALSE),"ERROR")) | AQ17: =IF(AE17="","",IFERROR(VLOOKUP(AE17,角色_装备!B:C,2,FALSE),"ERROR")) | AR17: =IF(AF17="","",IFERROR(VLOOKUP(AF17,角色_装备!B:C,2,FALSE),"ERROR")) | AS17: =IF(AG17="","",IFERROR(VLOOKUP(AG17,角色_装备!B:C,2,FALSE),"ERROR")) | AW17: =IF(AK17="","",IFERROR(VLOOKUP(AK17,角色_装备!B:C,2,FALSE),"ERROR")) | AX17: =IF(AL17="","",IFERROR(VLOOKUP(AL17,角色_装备!B:C,2,FALSE),"ERROR")) | AY17: =IF(AM17="","",IFERROR(VLOOKUP(AM17,角色_装备!B:C,2,FALSE),"ERROR"))
E18: =IF(D18="","",IFERROR(VLOOKUP(D18,角色_种族_友方!B:C,2,FALSE),"ERROR")) | AB18: =IF(Y18="","",IFERROR(VLOOKUP(Y18,角色_能力!B:C,2,FALSE),"ERROR")) | AC18: =IF(Z18="","",IFERROR(VLOOKUP(Z18,角色_能力!B:C,2,FALSE),"ERROR")) | AQ18: =IF(AE18="","",IFERROR(VLOOKUP(AE18,角色_装备!B:C,2,FALSE),"ERROR")) | AR18: =IF(AF18="","",IFERROR(VLOOKUP(AF18,角色_装备!B:C,2,FALSE),"ERROR")) | AS18: =IF(AG18="","",IFERROR(VLOOKUP(AG18,角色_装备!B:C,2,FALSE),"ERROR")) | AW18: =IF(AK18="","",IFERROR(VLOOKUP(AK18,角色_装备!B:C,2,FALSE),"ERROR")) | AX18: =IF(AL18="","",IFERROR(VLOOKUP(AL18,角色_装备!B:C,2,FALSE),"ERROR")) | AY18: =IF(AM18="","",IFERROR(VLOOKUP(AM18,角色_装备!B:C,2,FALSE),"ERROR"))
E19: =IF(D19="","",IFERROR(VLOOKUP(D19,角色_种族_友方!B:C,2,FALSE),"ERROR")) | AB19: =IF(Y19="","",IFERROR(VLOOKUP(Y19,角色_能力!B:C,2,FALSE),"ERROR")) | AC19: =IF(Z19="","",IFERROR(VLOOKUP(Z19,角色_能力!B:C,2,FALSE),"ERROR")) | AQ19: =IF(AE19="","",IFERROR(VLOOKUP(AE19,角色_装备!B:C,2,FALSE),"ERROR")) | AR19: =IF(AF19="","",IFERROR(VLOOKUP(AF19,角色_装备!B:C,2,FALSE),"ERROR")) | AS19: =IF(AG19="","",IFERROR(VLOOKUP(AG19,角色_装备!B:C,2,FALSE),"ERROR")) | AW19: =IF(AK19="","",IFERROR(VLOOKUP(AK19,角色_装备!B:C,2,FALSE),"ERROR")) | AX19: =IF(AL19="","",IFERROR(VLOOKUP(AL19,角色_装备!B:C,2,FALSE),"ERROR")) | AY19: =IF(AM19="","",IFERROR(VLOOKUP(AM19,角色_装备!B:C,2,FALSE),"ERROR"))
E20: =IF(D20="","",IFERROR(VLOOKUP(D20,角色_种族_友方!B:C,2,FALSE),"ERROR")) | AB20: =IF(Y20="","",IFERROR(VLOOKUP(Y20,角色_能力!B:C,2,FALSE),"ERROR")) | AC20: =IF(Z20="","",IFERROR(VLOOKUP(Z20,角色_能力!B:C,2,FALSE),"ERROR")) | AQ20: =IF(AE20="","",IFERROR(VLOOKUP(AE20,角色_装备!B:C,2,FALSE),"ERROR")) | AR20: =IF(AF20="","",IFERROR(VLOOKUP(AF20,角色_装备!B:C,2,FALSE),"ERROR")) | AS20: =IF(AG20="","",IFERROR(VLOOKUP(AG20,角色_装备!B:C,2,FALSE),"ERROR")) | AW20: =IF(AK20="","",IFERROR(VLOOKUP(AK20,角色_装备!B:C,2,FALSE),"ERROR")) | AX20: =IF(AL20="","",IFERROR(VLOOKUP(AL20,角色_装备!B:C,2,FALSE),"ERROR")) | AY20: =IF(AM20="","",IFERROR(VLOOKUP(AM20,角色_装备!B:C,2,FALSE),"ERROR"))
E21: =IF(D21="","",IFERROR(VLOOKUP(D21,角色_种族_友方!B:C,2,FALSE),"ERROR")) | AB21: =IF(Y21="","",IFERROR(VLOOKUP(Y21,角色_能力!B:C,2,FALSE),"ERROR")) | AC21: =IF(Z21="","",IFERROR(VLOOKUP(Z21,角色_能力!B:C,2,FALSE),"ERROR")) | AQ21: =IF(AE21="","",IFERROR(VLOOKUP(AE21,角色_装备!B:C,2,FALSE),"ERROR")) | AR21: =IF(AF21="","",IFERROR(VLOOKUP(AF21,角色_装备!B:C,2,FALSE),"ERROR")) | AS21: =IF(AG21="","",IFERROR(VLOOKUP(AG21,角色_装备!B:C,2,FALSE),"ERROR")) | AW21: =IF(AK21="","",IFERROR(VLOOKUP(AK21,角色_装备!B:C,2,FALSE),"ERROR")) | AX21: =IF(AL21="","",IFERROR(VLOOKUP(AL21,角色_装备!B:C,2,FALSE),"ERROR")) | AY21: =IF(AM21="","",IFERROR(VLOOKUP(AM21,角色_装备!B:C,2,FALSE),"ERROR"))
E22: =IF(D22="","",IFERROR(VLOOKUP(D22,角色_种族_友方!B:C,2,FALSE),"ERROR")) | AB22: =IF(Y22="","",IFERROR(VLOOKUP(Y22,角色_能力!B:C,2,FALSE),"ERROR")) | AC22: =IF(Z22="","",IFERROR(VLOOKUP(Z22,角色_能力!B:C,2,FALSE),"ERROR")) | AQ22: =IF(AE22="","",IFERROR(VLOOKUP(AE22,角色_装备!B:C,2,FALSE),"ERROR")) | AR22: =IF(AF22="","",IFERROR(VLOOKUP(AF22,角色_装备!B:C,2,FALSE),"ERROR")) | AS22: =IF(AG22="","",IFERROR(VLOOKUP(AG22,角色_装备!B:C,2,FALSE),"ERROR")) | AW22: =IF(AK22="","",IFERROR(VLOOKUP(AK22,角色_装备!B:C,2,FALSE),"ERROR")) | AX22: =IF(AL22="","",IFERROR(VLOOKUP(AL22,角色_装备!B:C,2,FALSE),"ERROR")) | AY22: =IF(AM22="","",IFERROR(VLOOKUP(AM22,角色_装备!B:C,2,FALSE),"ERROR"))
E23: =IF(D23="","",IFERROR(VLOOKUP(D23,角色_种族_友方!B:C,2,FALSE),"ERROR")) | AB23: =IF(Y23="","",IFERROR(VLOOKUP(Y23,角色_能力!B:C,2,FALSE),"ERROR")) | AC23: =IF(Z23="","",IFERROR(VLOOKUP(Z23,角色_能力!B:C,2,FALSE),"ERROR")) | AQ23: =IF(AE23="","",IFERROR(VLOOKUP(AE23,角色_装备!B:C,2,FALSE),"ERROR")) | AR23: =IF(AF23="","",IFERROR(VLOOKUP(AF23,角色_装备!B:C,2,FALSE),"ERROR")) | AS23: =IF(AG23="","",IFERROR(VLOOKUP(AG23,角色_装备!B:C,2,FALSE),"ERROR")) | AW23: =IF(AK23="","",IFERROR(VLOOKUP(AK23,角色_装备!B:C,2,FALSE),"ERROR")) | AX23: =IF(AL23="","",IFERROR(VLOOKUP(AL23,角色_装备!B:C,2,FALSE),"ERROR")) | AY23: =IF(AM23="","",IFERROR(VLOOKUP(AM23,角色_装备!B:C,2,FALSE),"ERROR"))
E24: =IF(D24="","",IFERROR(VLOOKUP(D24,角色_种族_友方!B:C,2,FALSE),"ERROR")) | AB24: =IF(Y24="","",IFERROR(VLOOKUP(Y24,角色_能力!B:C,2,FALSE),"ERROR")) | AC24: =IF(Z24="","",IFERROR(VLOOKUP(Z24,角色_能力!B:C,2,FALSE),"ERROR")) | AQ24: =IF(AE24="","",IFERROR(VLOOKUP(AE24,角色_装备!B:C,2,FALSE),"ERROR")) | AR24: =IF(AF24="","",IFERROR(VLOOKUP(AF24,角色_装备!B:C,2,FALSE),"ERROR")) | AS24: =IF(AG24="","",IFERROR(VLOOKUP(AG24,角色_装备!B:C,2,FALSE),"ERROR")) | AW24: =IF(AK24="","",IFERROR(VLOOKUP(AK24,角色_装备!B:C,2,FALSE),"ERROR")) | AX24: =IF(AL24="","",IFERROR(VLOOKUP(AL24,角色_装备!B:C,2,FALSE),"ERROR")) | AY24: =IF(AM24="","",IFERROR(VLOOKUP(AM24,角色_装备!B:C,2,FALSE),"ERROR"))
... E33: =IF(D33="","",IFERROR(VLOOKUP(D33,角色_种族_友方!B:C,2,FALSE),"ERROR")) | AB33: =IF(Y33="","",IFERROR(VLOOKUP(Y33,角色_能力!B:C,2,FALSE),"ERROR")) | AC33: =IF(Z33="","",IFERROR(VLOOKUP(Z33,角色_能力!B:C,2,FALSE),"ERROR")) | AQ33: =IF(AE33="","",IFERROR(VLOOKUP(AE33,角色_装备!B:C,2,FALSE),"ERROR")) | AR33: =IF(AF33="","",IFERROR(VLOOKUP(AF33,角色_装备!B:C,2,FALSE),"ERROR")) | AS33: =IF(AG33="","",IFERROR(VLOOKUP(AG33,角色_装备!B:C,2,FALSE),"ERROR")) | AW33: =IF(AK33="","",IFERROR(VLOOKUP(AK33,角色_装备!B:C,2,FALSE),"ERROR")) | AX33: =IF(AL33="","",IFERROR(VLOOKUP(AL33,角色_装备!B:C,2,FALSE),"ERROR")) | AY33: =IF(AM33="","",IFERROR(VLOOKUP(AM33,角色_装备!B:C,2,FALSE),"ERROR"))
E34: =IF(D34="","",IFERROR(VLOOKUP(D34,角色_种族_友方!B:C,2,FALSE),"ERROR")) | AB34: =IF(Y34="","",IFERROR(VLOOKUP(Y34,角色_能力!B:C,2,FALSE),"ERROR")) | AC34: =IF(Z34="","",IFERROR(VLOOKUP(Z34,角色_能力!B:C,2,FALSE),"ERROR")) | AQ34: =IF(AE34="","",IFERROR(VLOOKUP(AE34,角色_装备!B:C,2,FALSE),"ERROR")) | AR34: =IF(AF34="","",IFERROR(VLOOKUP(AF34,角色_装备!B:C,2,FALSE),"ERROR")) | AS34: =IF(AG34="","",IFERROR(VLOOKUP(AG34,角色_装备!B:C,2,FALSE),"ERROR")) | AX34: =IF(AL34="","",IFERROR(VLOOKUP(AL34,角色_装备!B:C,2,FALSE),"ERROR")) | AY34: =IF(AM34="","",IFERROR(VLOOKUP(AM34,角色_装备!B:C,2,FALSE),"ERROR"))
